<sdf version='1.7'>
  <world name='default'>
    <light name='sun' type='directional'>
      <cast_shadows>1</cast_shadows>
      <pose>0 0 10 0 -0 0</pose>
      <diffuse>0.8 0.8 0.8 1</diffuse>
      <specular>0.2 0.2 0.2 1</specular>
      <attenuation>
        <range>1000</range>
        <constant>0.9</constant>
        <linear>0.01</linear>
        <quadratic>0.001</quadratic>
      </attenuation>
      <direction>-0.5 0.1 -0.9</direction>
      <spot>
        <inner_angle>0</inner_angle>
        <outer_angle>0</outer_angle>
        <falloff>0</falloff>
      </spot>
    </light>
    <model name='ground_plane'>
      <static>1</static>
      <link name='link'>
        <collision name='collision'>
          <geometry>
            <plane>
              <normal>0 0 1</normal>
              <size>100 100</size>
            </plane>
          </geometry>
          <surface>
            <contact>
              <collide_bitmask>65535</collide_bitmask>
              <ode/>
            </contact>
            <friction>
              <ode>
                <mu>100</mu>
                <mu2>50</mu2>
              </ode>
              <torsional>
                <ode/>
              </torsional>
            </friction>
            <bounce/>
          </surface>
          <max_contacts>10</max_contacts>
        </collision>
        <visual name='visual'>
          <cast_shadows>0</cast_shadows>
          <geometry>
            <plane>
              <normal>0 0 1</normal>
              <size>100 100</size>
            </plane>
          </geometry>
          <material>
            <script>
              <uri>file://media/materials/scripts/gazebo.material</uri>
              <name>Gazebo/Grey</name>
            </script>
          </material>
        </visual>
        <self_collide>0</self_collide>
        <enable_wind>0</enable_wind>
        <kinematic>0</kinematic>
      </link>
    </model>
    <gravity>0 0 -9.8</gravity>
    <magnetic_field>6e-06 2.3e-05 -4.2e-05</magnetic_field>
    <atmosphere type='adiabatic'/>
    <physics type='ode'>
      <max_step_size>0.001</max_step_size>
      <real_time_factor>1</real_time_factor>
      <real_time_update_rate>1000</real_time_update_rate>
    </physics>
    <scene>
      <ambient>0.4 0.4 0.4 1</ambient>
      <background>0.7 0.7 0.7 1</background>
      <shadows>1</shadows>
    </scene>
    <wind/>
    <spherical_coordinates>
      <surface_model>EARTH_WGS84</surface_model>
      <latitude_deg>0</latitude_deg>
      <longitude_deg>0</longitude_deg>
      <elevation>0</elevation>
      <heading_deg>0</heading_deg>
    </spherical_coordinates>
    <model name='rover_ackermann'>
      <pose>0.933181 -1.48324 0.04 0 -0 0</pose>
      <self_collide>0</self_collide>
      <static>0</static>
      <link name='base_link'>
        <inertial>
          <pose>0 0 0 0 -0 0</pose>
          <mass>3</mass>
          <inertia>
            <ixx>0.0054</ixx>
            <ixy>0</ixy>
            <ixz>0</ixz>
            <iyy>0.0252</iyy>
            <iyz>0</iyz>
            <izz>0.0252</izz>
          </inertia>
        </inertial>
        <visual name='rover_ackermann/BaseVisual'>
          <pose>0 0 -0.0115 -0.018 -0 -1.5707</pose>
          <geometry>
            <mesh>
              <uri>https://fuel.ignitionrobotics.org/1.0/px4/models/rover_ackermann/1/files/meshes/MainBody.dae</uri>
            </mesh>
          </geometry>
        </visual>
        <collision name='rover_ackermann/BaseCollision'>
          <pose>-0.03 0 0.03 0 -0 0</pose>
          <geometry>
            <box>
              <size>0.45 0.1 0.08</size>
            </box>
          </geometry>
          <max_contacts>10</max_contacts>
          <surface>
            <contact>
              <ode/>
            </contact>
            <bounce/>
            <friction>
              <torsional>
                <ode/>
              </torsional>
              <ode/>
            </friction>
          </surface>
        </collision>
        <sensor name='imu_sensor' type='imu'>
          <always_on>1</always_on>
          <update_rate>250</update_rate>
          <imu>
            <angular_velocity>
              <x>
                <noise type='gaussian'>
                  <mean>0</mean>
                  <stddev>0.0003394</stddev>
                  <dynamic_bias_stddev>3.8785e-05</dynamic_bias_stddev>
                  <dynamic_bias_correlation_time>1000</dynamic_bias_correlation_time>
                </noise>
              </x>
              <y>
                <noise type='gaussian'>
                  <mean>0</mean>
                  <stddev>0.0003394</stddev>
                  <dynamic_bias_stddev>3.8785e-05</dynamic_bias_stddev>
                  <dynamic_bias_correlation_time>1000</dynamic_bias_correlation_time>
                </noise>
              </y>
              <z>
                <noise type='gaussian'>
                  <mean>0</mean>
                  <stddev>0.0003394</stddev>
                  <dynamic_bias_stddev>3.8785e-05</dynamic_bias_stddev>
                  <dynamic_bias_correlation_time>1000</dynamic_bias_correlation_time>
                </noise>
              </z>
            </angular_velocity>
            <linear_acceleration>
              <x>
                <noise type='gaussian'>
                  <mean>0</mean>
                  <stddev>0.004</stddev>
                  <dynamic_bias_stddev>0.006</dynamic_bias_stddev>
                  <dynamic_bias_correlation_time>300</dynamic_bias_correlation_time>
                </noise>
              </x>
              <y>
                <noise type='gaussian'>
                  <mean>0</mean>
                  <stddev>0.004</stddev>
                  <dynamic_bias_stddev>0.006</dynamic_bias_stddev>
                  <dynamic_bias_correlation_time>300</dynamic_bias_correlation_time>
                </noise>
              </y>
              <z>
                <noise type='gaussian'>
                  <mean>0</mean>
                  <stddev>0.004</stddev>
                  <dynamic_bias_stddev>0.006</dynamic_bias_stddev>
                  <dynamic_bias_correlation_time>300</dynamic_bias_correlation_time>
                </noise>
              </z>
            </linear_acceleration>
          </imu>
        </sensor>
        <sensor name='air_pressure_sensor' type='air_pressure'>
          <always_on>1</always_on>
          <update_rate>50</update_rate>
          <air_pressure>
            <pressure>
              <noise type='gaussian'>
                <mean>0</mean>
                <stddev>0.01</stddev>
              </noise>
            </pressure>
          </air_pressure>
        </sensor>
        <sensor name='navsat_sensor' type='navsat'>
          <always_on>1</always_on>
          <update_rate>30</update_rate>
          <gps/>
        </sensor>
        <self_collide>0</self_collide>
        <enable_wind>0</enable_wind>
        <kinematic>0</kinematic>
      </link>
      <link name='rover_ackermann/FrontRightWheel'>
        <pose relative_to='rover_ackermann/FrontRightWheelJoint'>0 0 0 0 -0 0</pose>
        <inertial>
          <mass>0.05</mass>
          <inertia>
            <ixx>3.331e-05</ixx>
            <ixy>0</ixy>
            <ixz>0</ixz>
            <iyy>2.04e-05</iyy>
            <iyz>0</iyz>
            <izz>2.04e-05</izz>
          </inertia>
          <pose>0 0 0 0 -0 0</pose>
        </inertial>
        <gravity>1</gravity>
        <velocity_decay/>
        <visual name='rover_ackermann/FrontRightWheelVisual'>
          <pose relative_to='rover_ackermann/FrontRightWheelJoint'>0 -0.02 0 0 -0 3.14159</pose>
          <geometry>
            <mesh>
              <uri>https://fuel.ignitionrobotics.org/1.0/px4/models/rover_ackermann/1/files/meshes/Wheel.dae</uri>
            </mesh>
          </geometry>
        </visual>
        <collision name='rover_ackermann/FrontRightWheelCollision'>
          <pose relative_to='rover_ackermann/FrontRightWheelJoint'>0 0 0 -1.5707 0 0</pose>
          <geometry>
            <cylinder>
              <length>0.03</length>
              <radius>0.06</radius>
            </cylinder>
          </geometry>
          <surface>
            <friction>
              <ode>
                <mu>1</mu>
                <mu2>1</mu2>
                <fdir1>1 0 0</fdir1>
              </ode>
              <torsional>
                <ode/>
              </torsional>
            </friction>
            <contact>
              <ode/>
            </contact>
            <bounce/>
          </surface>
          <max_contacts>10</max_contacts>
        </collision>
        <self_collide>0</self_collide>
        <enable_wind>0</enable_wind>
        <kinematic>0</kinematic>
      </link>
      <link name='rover_ackermann/FrontRightWheelSteering'>
        <pose relative_to='servo_1'>0 0 0 0 -0 0</pose>
        <inertial>
          <mass>0.005</mass>
          <inertia>
            <ixx>1.8e-06</ixx>
            <iyy>1.8e-06</iyy>
            <izz>1.8e-06</izz>
            <ixy>0</ixy>
            <ixz>0</ixz>
            <iyz>0</iyz>
          </inertia>
          <pose>0 0 0 0 -0 0</pose>
        </inertial>
        <self_collide>0</self_collide>
        <enable_wind>0</enable_wind>
        <kinematic>0</kinematic>
      </link>
      <link name='rover_ackermann/FrontLeftWheel'>
        <pose relative_to='rover_ackermann/FrontLeftWheelJoint'>0 0 0 0 -0 0</pose>
        <inertial>
          <mass>0.05</mass>
          <inertia>
            <ixx>3.331e-05</ixx>
            <ixy>0</ixy>
            <ixz>0</ixz>
            <iyy>2.04e-05</iyy>
            <iyz>0</iyz>
            <izz>2.04e-05</izz>
          </inertia>
          <pose>0 0 0 0 -0 0</pose>
        </inertial>
        <gravity>1</gravity>
        <velocity_decay/>
        <visual name='rover_ackermann/FrontLeftWheelVisual'>
          <pose relative_to='rover_ackermann/FrontLeftWheelJoint'>0 -0.02 0 0 -0 3.14159</pose>
          <geometry>
            <mesh>
              <uri>https://fuel.ignitionrobotics.org/1.0/px4/models/rover_ackermann/1/files/meshes/Wheel.dae</uri>
            </mesh>
          </geometry>
        </visual>
        <collision name='rover_ackermann/FrontLeftWheelCollision'>
          <pose relative_to='rover_ackermann/FrontLeftWheelJoint'>0 0 0 -1.5707 0 0</pose>
          <geometry>
            <cylinder>
              <length>0.03</length>
              <radius>0.06</radius>
            </cylinder>
          </geometry>
          <surface>
            <friction>
              <ode>
                <mu>1</mu>
                <mu2>1</mu2>
                <fdir1>1 0 0</fdir1>
              </ode>
              <torsional>
                <ode/>
              </torsional>
            </friction>
            <contact>
              <ode/>
            </contact>
            <bounce/>
          </surface>
          <max_contacts>10</max_contacts>
        </collision>
        <self_collide>0</self_collide>
        <enable_wind>0</enable_wind>
        <kinematic>0</kinematic>
      </link>
      <link name='rover_ackermann/FrontLeftWheelSteering'>
        <pose relative_to='servo_0'>0 0 0 0 -0 0</pose>
        <inertial>
          <mass>0.005</mass>
          <inertia>
            <ixx>1.8e-06</ixx>
            <iyy>1.8e-06</iyy>
            <izz>1.8e-06</izz>
            <ixy>0</ixy>
            <ixz>0</ixz>
            <iyz>0</iyz>
          </inertia>
          <pose>0 0 0 0 -0 0</pose>
        </inertial>
        <self_collide>0</self_collide>
        <enable_wind>0</enable_wind>
        <kinematic>0</kinematic>
      </link>
      <link name='rover_ackermann/RearRightWheel'>
        <pose relative_to='rover_ackermann/RearRightWheelJoint'>0 0 0 0 -0 0</pose>
        <inertial>
          <mass>0.05</mass>
          <inertia>
            <ixx>3.331e-05</ixx>
            <ixy>0</ixy>
            <ixz>0</ixz>
            <iyy>2.04e-05</iyy>
            <iyz>0</iyz>
            <izz>2.04e-05</izz>
          </inertia>
          <pose>0 0 0 0 -0 0</pose>
        </inertial>
        <gravity>1</gravity>
        <velocity_decay/>
        <visual name='rover_ackermann/RearRightWheelVisual'>
          <pose relative_to='rover_ackermann/RearRightWheelJoint'>0 -0.02 0 0 -0 3.14159</pose>
          <geometry>
            <mesh>
              <uri>https://fuel.ignitionrobotics.org/1.0/px4/models/rover_ackermann/1/files/meshes/Wheel.dae</uri>
            </mesh>
          </geometry>
        </visual>
        <collision name='rover_ackermann/RearRightWheelCollision'>
          <pose relative_to='rover_ackermann/RearRightWheelJoint'>0 0 0 -1.5707 0 0</pose>
          <geometry>
            <cylinder>
              <length>0.03</length>
              <radius>0.06</radius>
            </cylinder>
          </geometry>
          <surface>
            <friction>
              <ode>
                <mu>1</mu>
                <mu2>1</mu2>
                <fdir1>1 0 0</fdir1>
              </ode>
              <torsional>
                <ode/>
              </torsional>
            </friction>
            <contact>
              <ode/>
            </contact>
            <bounce/>
          </surface>
          <max_contacts>10</max_contacts>
        </collision>
        <self_collide>0</self_collide>
        <enable_wind>0</enable_wind>
        <kinematic>0</kinematic>
      </link>
      <link name='rover_ackermann/RearLeftWheel'>
        <pose relative_to='rover_ackermann/RearLeftWheelJoint'>0 0 0 0 -0 0</pose>
        <inertial>
          <mass>0.05</mass>
          <inertia>
            <ixx>3.331e-05</ixx>
            <ixy>0</ixy>
            <ixz>0</ixz>
            <iyy>2.04e-05</iyy>
            <iyz>0</iyz>
            <izz>2.04e-05</izz>
          </inertia>
          <pose>0 0 0 0 -0 0</pose>
        </inertial>
        <gravity>1</gravity>
        <velocity_decay/>
        <visual name='rover_ackermann/RearLeftWheelVisual'>
          <pose relative_to='rover_ackermann/RearLeftWheelJoint'>0 -0.02 0 0 -0 3.14159</pose>
          <geometry>
            <mesh>
              <uri>https://fuel.ignitionrobotics.org/1.0/px4/models/rover_ackermann/1/files/meshes/Wheel.dae</uri>
            </mesh>
          </geometry>
        </visual>
        <collision name='rover_ackermann/RearLeftWheelCollision'>
          <pose relative_to='rover_ackermann/RearLeftWheelJoint'>0 0 0 -1.5707 0 0</pose>
          <geometry>
            <cylinder>
              <length>0.03</length>
              <radius>0.06</radius>
            </cylinder>
          </geometry>
          <surface>
            <friction>
              <ode>
                <mu>1</mu>
                <mu2>1</mu2>
                <fdir1>1 0 0</fdir1>
              </ode>
              <torsional>
                <ode/>
              </torsional>
            </friction>
            <contact>
              <ode/>
            </contact>
            <bounce/>
          </surface>
          <max_contacts>10</max_contacts>
        </collision>
        <self_collide>0</self_collide>
        <enable_wind>0</enable_wind>
        <kinematic>0</kinematic>
      </link>
      <joint name='servo_1' type='revolute'>
        <parent>base_link</parent>
        <child>rover_ackermann/FrontRightWheelSteering</child>
        <pose relative_to='base_link'>0.12 -0.1 0 0 -0 0</pose>
        <axis>
          <xyz>0 0 1</xyz>
          <limit>
            <lower>-0.5236</lower>
            <upper>0.5236</upper>
            <velocity>1</velocity>
            <effort>25</effort>
          </limit>
          <dynamics>
            <spring_reference>0</spring_reference>
            <spring_stiffness>0</spring_stiffness>
          </dynamics>
          <use_parent_model_frame>1</use_parent_model_frame>
        </axis>
      </joint>
      <joint name='servo_0' type='revolute'>
        <parent>base_link</parent>
        <child>rover_ackermann/FrontLeftWheelSteering</child>
        <pose relative_to='base_link'>0.12 0.1 0 0 -0 0</pose>
        <axis>
          <xyz>0 0 1</xyz>
          <limit>
            <lower>-0.5236</lower>
            <upper>0.5236</upper>
            <velocity>1</velocity>
            <effort>25</effort>
          </limit>
          <dynamics>
            <spring_reference>0</spring_reference>
            <spring_stiffness>0</spring_stiffness>
          </dynamics>
          <use_parent_model_frame>1</use_parent_model_frame>
        </axis>
      </joint>
      <joint name='rover_ackermann/FrontRightWheelJoint' type='revolute'>
        <parent>rover_ackermann/FrontRightWheelSteering</parent>
        <child>rover_ackermann/FrontRightWheel</child>
        <pose relative_to='servo_1'>0 0 0 0 -0 0</pose>
        <axis>
          <xyz>0 1 0</xyz>
          <limit>
            <lower>-1.79769e+308</lower>
            <upper>1.79769e+308</upper>
            <velocity>50</velocity>
          </limit>
          <dynamics>
            <spring_reference>0</spring_reference>
            <spring_stiffness>0</spring_stiffness>
          </dynamics>
          <use_parent_model_frame>1</use_parent_model_frame>
        </axis>
      </joint>
      <joint name='rover_ackermann/FrontLeftWheelJoint' type='revolute'>
        <parent>rover_ackermann/FrontLeftWheelSteering</parent>
        <child>rover_ackermann/FrontLeftWheel</child>
        <pose relative_to='servo_0'>0 0 0 0 -0 0</pose>
        <axis>
          <xyz>0 1 0</xyz>
          <limit>
            <lower>-1.79769e+308</lower>
            <upper>1.79769e+308</upper>
            <velocity>50</velocity>
          </limit>
          <dynamics>
            <spring_reference>0</spring_reference>
            <spring_stiffness>0</spring_stiffness>
          </dynamics>
          <use_parent_model_frame>1</use_parent_model_frame>
        </axis>
      </joint>
      <joint name='rover_ackermann/RearRightWheelJoint' type='revolute'>
        <parent>base_link</parent>
        <child>rover_ackermann/RearRightWheel</child>
        <pose relative_to='base_link'>-0.192 -0.1 0 0 -0 0</pose>
        <axis>
          <xyz>0 1 0</xyz>
          <limit>
            <lower>-1.79769e+308</lower>
            <upper>1.79769e+308</upper>
            <velocity>50</velocity>
          </limit>
          <dynamics>
            <spring_reference>0</spring_reference>
            <spring_stiffness>0</spring_stiffness>
          </dynamics>
          <use_parent_model_frame>1</use_parent_model_frame>
        </axis>
      </joint>
      <joint name='rover_ackermann/RearLeftWheelJoint' type='revolute'>
        <parent>base_link</parent>
        <child>rover_ackermann/RearLeftWheel</child>
        <pose relative_to='base_link'>-0.192 0.1 0 0 -0 0</pose>
        <axis>
          <xyz>0 1 0</xyz>
          <limit>
            <lower>-1.79769e+308</lower>
            <upper>1.79769e+308</upper>
            <velocity>50</velocity>
          </limit>
          <dynamics>
            <spring_reference>0</spring_reference>
            <spring_stiffness>0</spring_stiffness>
          </dynamics>
          <use_parent_model_frame>1</use_parent_model_frame>
        </axis>
      </joint>
      <plugin name='gz::sim::systems::JointController' filename='gz-sim-joint-controller-system'>
        <joint_name>rover_ackermann/FrontLeftWheelJoint</joint_name>
        <sub_topic>command/motor_speed</sub_topic>
        <use_actuator_msg>1</use_actuator_msg>
        <actuator_number>0</actuator_number>
        <p_gain>10.0</p_gain>
      </plugin>
      <plugin name='gz::sim::systems::JointController' filename='gz-sim-joint-controller-system'>
        <joint_name>rover_ackermann/FrontRightWheelJoint</joint_name>
        <sub_topic>command/motor_speed</sub_topic>
        <use_actuator_msg>1</use_actuator_msg>
        <actuator_number>0</actuator_number>
        <p_gain>10.0</p_gain>
      </plugin>
      <plugin name='gz::sim::systems::JointController' filename='gz-sim-joint-controller-system'>
        <joint_name>rover_ackermann/RearRightWheelJoint</joint_name>
        <sub_topic>command/motor_speed</sub_topic>
        <use_actuator_msg>1</use_actuator_msg>
        <actuator_number>0</actuator_number>
        <p_gain>10.0</p_gain>
      </plugin>
      <plugin name='gz::sim::systems::JointController' filename='gz-sim-joint-controller-system'>
        <joint_name>rover_ackermann/RearLeftWheelJoint</joint_name>
        <sub_topic>command/motor_speed</sub_topic>
        <use_actuator_msg>1</use_actuator_msg>
        <actuator_number>0</actuator_number>
        <p_gain>10.0</p_gain>
      </plugin>
      <plugin name='gz::sim::systems::JointStatePublisher' filename='gz-sim-joint-state-publisher-system'>
        <joint_name>rover_ackermann/FrontLeftWheelJoint</joint_name>
        <joint_name>rover_ackermann/FrontRightWheelJoint</joint_name>
        <joint_name>rover_ackermann/RearLeftWheelJoint</joint_name>
        <joint_name>rover_ackermann/RearLeftWheelJoint</joint_name>
        <joint_name>servo_0</joint_name>
        <joint_name>servo_1</joint_name>
      </plugin>
      <plugin name='gz::sim::systems::JointPositionController' filename='gz-sim-joint-position-controller-system'>
        <joint_name>servo_0</joint_name>
        <sub_topic>servo_0</sub_topic>
        <p_gain>10</p_gain>
        <i_gain>0</i_gain>
        <d_gain>0</d_gain>
      </plugin>
      <plugin name='gz::sim::systems::JointPositionController' filename='gz-sim-joint-position-controller-system'>
        <joint_name>servo_1</joint_name>
        <sub_topic>servo_0</sub_topic>
        <p_gain>10</p_gain>
        <i_gain>0</i_gain>
        <d_gain>0</d_gain>
      </plugin>
    </model>
    <model name='zero_turn_mower'>
      <pose>-4.7569 0.257035 0.246 0 -0 0</pose>
      <link name='base_link'>
        <pose>0 0 0 0 -0 0</pose>
        <inertial>
          <pose>0 0 0 0 -0 0</pose>
          <mass>220</mass>
          <inertia>
            <ixx>40</ixx>
            <ixy>0</ixy>
            <iyy>150</iyy>
            <ixz>0</ixz>
            <iyz>0</iyz>
            <izz>150</izz>
          </inertia>
        </inertial>
        <collision name='base_collision'>
          <pose>0 0 0.2 0 -0 0</pose>
          <geometry>
            <box>
              <size>1.8 0.65 0.55</size>
            </box>
          </geometry>
          <surface>
            <contact>
              <ode/>
            </contact>
            <friction>
              <ode/>
              <torsional>
                <ode/>
              </torsional>
            </friction>
            <bounce/>
          </surface>
          <max_contacts>10</max_contacts>
        </collision>
        <visual name='base_visual_base'>
          <pose>0 0 0 0 -0 0</pose>
          <geometry>
            <box>
              <size>1.81 0.66 0.1</size>
            </box>
          </geometry>
          <material>
            <ambient>0.9 0.36 0 1</ambient>
            <diffuse>0.9 0.36 0 1</diffuse>
            <specular>0 0 0 0</specular>
            <emissive>0 0 0 1</emissive>
          </material>
        </visual>
        <visual name='base_visual'>
          <pose>-0.5 0 0.2 0 -0 0</pose>
          <geometry>
            <box>
              <size>0.8 0.65 0.55</size>
            </box>
          </geometry>
          <material>
            <ambient>1 0.4 0 1</ambient>
            <diffuse>1 0.4 0 1</diffuse>
            <specular>0 0 0 0</specular>
            <emissive>0.2 0.08 0 1</emissive>
          </material>
        </visual>
        <visual name='base_visual_cutter_r'>
          <pose>0.2 -0.5 -0.1 0 -0 0</pose>
          <geometry>
            <cylinder>
              <radius>0.25</radius>
              <length>0.1</length>
            </cylinder>
          </geometry>
          <material>
            <ambient>1 0.4 0 1</ambient>
            <diffuse>1 0.4 0 1</diffuse>
            <specular>0 0 0 0</specular>
            <emissive>0.2 0.08 0 1</emissive>
          </material>
        </visual>
        <visual name='base_visual_cutter_c'>
          <pose>0.23 0 -0.1 0 -0 0</pose>
          <geometry>
            <cylinder>
              <radius>0.25</radius>
              <length>0.1</length>
            </cylinder>
          </geometry>
          <material>
            <ambient>1 0.4 0 1</ambient>
            <diffuse>1 0.4 0 1</diffuse>
            <specular>0 0 0 0</specular>
            <emissive>0.2 0.08 0 1</emissive>
          </material>
        </visual>
        <visual name='base_visual_cutter_l'>
          <pose>0.2 0.5 -0.1 0 -0 0</pose>
          <geometry>
            <cylinder>
              <radius>0.25</radius>
              <length>0.1</length>
            </cylinder>
          </geometry>
          <material>
            <ambient>1 0.4 0 1</ambient>
            <diffuse>1 0.4 0 1</diffuse>
            <specular>0 0 0 0</specular>
            <emissive>0.2 0.08 0 1</emissive>
          </material>
        </visual>
        <collision name='left_caster_collision'>
          <pose>0.85 0.38 -0.1 0 -0 0</pose>
          <geometry>
            <sphere>
              <radius>0.1</radius>
            </sphere>
          </geometry>
          <surface>
            <friction>
              <ode>
                <mu>0</mu>
                <mu2>0</mu2>
                <slip1>1</slip1>
                <slip2>1</slip2>
              </ode>
              <torsional>
                <ode/>
              </torsional>
            </friction>
            <contact>
              <ode/>
            </contact>
            <bounce/>
          </surface>
          <max_contacts>10</max_contacts>
        </collision>
        <visual name='left_caster_visual_base'>
          <pose>0.85 0.38 -0.01 0 -0 0</pose>
          <geometry>
            <cylinder>
              <radius>0.1</radius>
              <length>0.1</length>
            </cylinder>
          </geometry>
          <material>
            <ambient>0.9 0.36 0 1</ambient>
            <diffuse>0.9 0.36 0 1</diffuse>
            <specular>0 0 0 0</specular>
            <emissive>0 0 0 1</emissive>
          </material>
        </visual>
        <visual name='left_caster_visual'>
          <pose>0.85 0.38 -0.1 0 -0 0</pose>
          <geometry>
            <sphere>
              <radius>0.1</radius>
            </sphere>
          </geometry>
          <material>
            <ambient>1 0.2 0.2 1</ambient>
            <diffuse>1 0.1 0.1 1</diffuse>
            <specular>0 0 0 0</specular>
            <emissive>0 0 0 1</emissive>
          </material>
        </visual>
        <collision name='right_caster_collision'>
          <pose>0.85 -0.38 -0.1 0 -0 0</pose>
          <geometry>
            <sphere>
              <radius>0.1</radius>
            </sphere>
          </geometry>
          <surface>
            <friction>
              <ode>
                <mu>0</mu>
                <mu2>0</mu2>
                <slip1>1</slip1>
                <slip2>1</slip2>
              </ode>
              <torsional>
                <ode/>
              </torsional>
            </friction>
            <contact>
              <ode/>
            </contact>
            <bounce/>
          </surface>
          <max_contacts>10</max_contacts>
        </collision>
        <visual name='right_caster_visual_base'>
          <pose>0.85 -0.38 -0.01 0 -0 0</pose>
          <geometry>
            <cylinder>
              <radius>0.1</radius>
              <length>0.1</length>
            </cylinder>
          </geometry>
          <material>
            <ambient>0.9 0.36 0 1</ambient>
            <diffuse>0.9 0.36 0 1</diffuse>
            <specular>0 0 0 0</specular>
            <emissive>0 0 0 1</emissive>
          </material>
        </visual>
        <visual name='right_caster_visual'>
          <pose>0.85 -0.38 -0.1 0 -0 0</pose>
          <geometry>
            <sphere>
              <radius>0.1</radius>
            </sphere>
          </geometry>
          <material>
            <ambient>0.2 1 0.2 1</ambient>
            <diffuse>0.1 1 0.1 1</diffuse>
            <specular>0 0 0 0</specular>
            <emissive>0 0 0 1</emissive>
          </material>
        </visual>
        <sensor name='air_pressure_sensor' type='air_pressure'>
          <always_on>1</always_on>
          <update_rate>50</update_rate>
          <air_pressure>
            <pressure>
              <noise type='gaussian'>
                <mean>0</mean>
                <stddev>0.01</stddev>
              </noise>
            </pressure>
          </air_pressure>
        </sensor>
        <sensor name='navsat_sensor' type='navsat'>
          <always_on>1</always_on>
          <update_rate>30</update_rate>
          <gps/>
        </sensor>
        <sensor name='imu_sensor' type='imu'>
          <always_on>1</always_on>
          <update_rate>250</update_rate>
          <imu>
            <angular_velocity>
              <x>
                <noise type='gaussian'>
                  <mean>0</mean>
                  <stddev>0.0003394</stddev>
                  <dynamic_bias_stddev>3.8785e-05</dynamic_bias_stddev>
                  <dynamic_bias_correlation_time>1000</dynamic_bias_correlation_time>
                </noise>
              </x>
              <y>
                <noise type='gaussian'>
                  <mean>0</mean>
                  <stddev>0.0003394</stddev>
                  <dynamic_bias_stddev>3.8785e-05</dynamic_bias_stddev>
                  <dynamic_bias_correlation_time>1000</dynamic_bias_correlation_time>
                </noise>
              </y>
              <z>
                <noise type='gaussian'>
                  <mean>0</mean>
                  <stddev>0.0003394</stddev>
                  <dynamic_bias_stddev>3.8785e-05</dynamic_bias_stddev>
                  <dynamic_bias_correlation_time>1000</dynamic_bias_correlation_time>
                </noise>
              </z>
            </angular_velocity>
            <linear_acceleration>
              <x>
                <noise type='gaussian'>
                  <mean>0</mean>
                  <stddev>0.004</stddev>
                  <dynamic_bias_stddev>0.006</dynamic_bias_stddev>
                  <dynamic_bias_correlation_time>300</dynamic_bias_correlation_time>
                </noise>
              </x>
              <y>
                <noise type='gaussian'>
                  <mean>0</mean>
                  <stddev>0.004</stddev>
                  <dynamic_bias_stddev>0.006</dynamic_bias_stddev>
                  <dynamic_bias_correlation_time>300</dynamic_bias_correlation_time>
                </noise>
              </y>
              <z>
                <noise type='gaussian'>
                  <mean>0</mean>
                  <stddev>0.004</stddev>
                  <dynamic_bias_stddev>0.006</dynamic_bias_stddev>
                  <dynamic_bias_correlation_time>300</dynamic_bias_correlation_time>
                </noise>
              </z>
            </linear_acceleration>
          </imu>
        </sensor>
        <self_collide>0</self_collide>
        <enable_wind>0</enable_wind>
        <kinematic>0</kinematic>
      </link>
      <link name='left_wheel_link'>
        <pose>-0.45 0.45 0.0215 1.57079 1.57079 3.14159</pose>
        <inertial>
          <mass>8</mass>
          <inertia>
            <ixx>0.5</ixx>
            <ixy>0</ixy>
            <iyy>0.5</iyy>
            <ixz>0</ixz>
            <iyz>0</iyz>
            <izz>1</izz>
          </inertia>
          <pose>0 0 0 0 -0 0</pose>
        </inertial>
        <collision name='left_wheel_link_collision'>
          <geometry>
            <cylinder>
              <radius>0.22</radius>
              <length>0.22</length>
            </cylinder>
          </geometry>
          <max_contacts>1</max_contacts>
          <surface>
            <friction>
              <ode>
                <mu>0.4</mu>
                <mu2>0.6</mu2>
              </ode>
              <torsional>
                <ode/>
              </torsional>
            </friction>
            <bounce/>
            <contact>
              <ode>
                <min_depth>0.005</min_depth>
                <kp>1e+08</kp>
              </ode>
            </contact>
          </surface>
        </collision>
        <visual name='left_wheel_link_visual'>
          <pose>0 0 0 1.5708 -0 0</pose>
          <geometry>
            <mesh>
              <scale>2.8 2 2.8</scale>
              <uri>https://fuel.ignitionrobotics.org/1.0/px4/models/lawnmower/1/files/meshes/wheel_link.STL</uri>
            </mesh>
          </geometry>
          <material>
            <script>
              <name>Gazebo/FlatBlack</name>
              <uri>file://media/materials/scripts/gazebo.material</uri>
            </script>
          </material>
        </visual>
        <visual name='left_wheel_marker_visual'>
          <pose>0.17 0 0 0 -0 0</pose>
          <geometry>
            <box>
              <size>0.1 0.01 0.21</size>
            </box>
          </geometry>
          <material>
            <ambient>1 0.2 0.2 1</ambient>
            <diffuse>1 0.1 0.1 1</diffuse>
            <specular>0 0 0 0</specular>
            <emissive>0 0 0 1</emissive>
          </material>
        </visual>
        <self_collide>0</self_collide>
        <enable_wind>0</enable_wind>
        <kinematic>0</kinematic>
      </link>
      <joint name='left_wheel_joint' type='revolute'>
        <child>left_wheel_link</child>
        <parent>base_link</parent>
        <axis>
          <xyz>0 0 1</xyz>
          <limit>
            <lower>-1e+16</lower>
            <upper>1e+16</upper>
          </limit>
          <dynamics>
            <spring_reference>0</spring_reference>
            <spring_stiffness>0</spring_stiffness>
          </dynamics>
        </axis>
      </joint>
      <link name='right_wheel_link'>
        <pose>-0.45 -0.45 0.0215 1.57079 1.57079 3.14159</pose>
        <inertial>
          <mass>8</mass>
          <inertia>
            <ixx>0.5</ixx>
            <ixy>0</ixy>
            <iyy>0.5</iyy>
            <ixz>0</ixz>
            <iyz>0</iyz>
            <izz>1</izz>
          </inertia>
          <pose>0 0 0 0 -0 0</pose>
        </inertial>
        <collision name='right_wheel_link_collision'>
          <geometry>
            <cylinder>
              <radius>0.22</radius>
              <length>0.22</length>
            </cylinder>
          </geometry>
          <max_contacts>1</max_contacts>
          <surface>
            <friction>
              <ode>
                <mu>0.4</mu>
                <mu2>0.6</mu2>
              </ode>
              <torsional>
                <ode/>
              </torsional>
            </friction>
            <bounce/>
            <contact>
              <ode>
                <min_depth>0.005</min_depth>
                <kp>1e+08</kp>
              </ode>
            </contact>
          </surface>
        </collision>
        <visual name='right_wheel_link_visual'>
          <pose>0 0 0 1.5708 -0 0</pose>
          <geometry>
            <mesh>
              <scale>2.8 2 2.8</scale>
              <uri>https://fuel.ignitionrobotics.org/1.0/px4/models/lawnmower/1/files/meshes/wheel_link.STL</uri>
            </mesh>
          </geometry>
          <material>
            <script>
              <name>Gazebo/FlatBlack</name>
              <uri>file://media/materials/scripts/gazebo.material</uri>
            </script>
          </material>
        </visual>
        <visual name='right_wheel_marker_visual'>
          <pose>0.17 0 0 0 -0 0</pose>
          <geometry>
            <box>
              <size>0.1 0.01 0.21</size>
            </box>
          </geometry>
          <material>
            <ambient>0.2 1 0.2 1</ambient>
            <diffuse>0.1 1 0.1 1</diffuse>
            <specular>0 0 0 0</specular>
            <emissive>0 0 0 1</emissive>
          </material>
        </visual>
        <self_collide>0</self_collide>
        <enable_wind>0</enable_wind>
        <kinematic>0</kinematic>
      </link>
      <joint name='right_wheel_joint' type='revolute'>
        <child>right_wheel_link</child>
        <parent>base_link</parent>
        <axis>
          <xyz>0 0 1</xyz>
          <limit>
            <lower>-1e+16</lower>
            <upper>1e+16</upper>
          </limit>
          <dynamics>
            <spring_reference>0</spring_reference>
            <spring_stiffness>0</spring_stiffness>
          </dynamics>
        </axis>
      </joint>
      <link name='engine_visual_link'>
        <pose>-0.9 0 0.5 0 -0 0</pose>
        <visual name='engine_visual_link_visual'>
          <pose>0 0 0 1.5708 -0 0</pose>
          <geometry>
            <cylinder>
              <radius>0.1</radius>
              <length>0.08</length>
            </cylinder>
          </geometry>
          <material>
            <ambient>0.3 0.3 0.2 1</ambient>
            <diffuse>1 1 0.1 1</diffuse>
            <specular>0 0 0 0</specular>
            <emissive>0 0 0 1</emissive>
          </material>
        </visual>
        <self_collide>0</self_collide>
        <inertial>
          <pose>0 0 0 0 -0 0</pose>
          <inertia>
            <ixx>1</ixx>
            <ixy>0</ixy>
            <ixz>0</ixz>
            <iyy>1</iyy>
            <iyz>0</iyz>
            <izz>1</izz>
          </inertia>
          <mass>1</mass>
        </inertial>
        <enable_wind>0</enable_wind>
        <kinematic>0</kinematic>
      </link>
      <joint name='engine_visual_joint' type='revolute'>
        <child>engine_visual_link</child>
        <parent>base_link</parent>
        <axis>
          <xyz>1 0 0</xyz>
          <limit>
            <lower>-1e+16</lower>
            <upper>1e+16</upper>
          </limit>
          <dynamics>
            <spring_reference>0</spring_reference>
            <spring_stiffness>0</spring_stiffness>
          </dynamics>
        </axis>
      </joint>
      <link name='cutter_blades_link'>
        <pose>0.2 0 -0.1 0 -0 0</pose>
        <visual name='cutter_blades_marker_visual'>
          <pose>0.8 0 0 0 -0 0</pose>
          <geometry>
            <box>
              <size>0.2 0.01 0.15</size>
            </box>
          </geometry>
          <material>
            <ambient>1 0 0 1</ambient>
            <diffuse>1 0 0 1</diffuse>
            <specular>0 0 0 0</specular>
            <emissive>0 0 0 1</emissive>
          </material>
        </visual>
        <self_collide>0</self_collide>
        <inertial>
          <pose>0 0 0 0 -0 0</pose>
          <inertia>
            <ixx>1</ixx>
            <ixy>0</ixy>
            <ixz>0</ixz>
            <iyy>1</iyy>
            <iyz>0</iyz>
            <izz>1</izz>
          </inertia>
          <mass>1</mass>
        </inertial>
        <enable_wind>0</enable_wind>
        <kinematic>0</kinematic>
      </link>
      <joint name='cutter_blades_joint' type='revolute'>
        <child>cutter_blades_link</child>
        <parent>base_link</parent>
        <axis>
          <xyz>0 0 1</xyz>
          <limit>
            <lower>-1e+16</lower>
            <upper>1e+16</upper>
          </limit>
          <dynamics>
            <spring_reference>0</spring_reference>
            <spring_stiffness>0</spring_stiffness>
          </dynamics>
        </axis>
      </joint>
      <link name='alarm_visual_link'>
        <pose>-0.45 0 0.65 0 -0 0</pose>
        <visual name='alarm_visual_sphere_visual'>
          <pose>0 0 0 1.5708 -0 0</pose>
          <geometry>
            <sphere>
              <radius>0.07</radius>
            </sphere>
          </geometry>
          <material>
            <ambient>0.7 0.7 0 1</ambient>
            <diffuse>0.7 0.7 0 1</diffuse>
            <specular>0 0 0 0</specular>
            <emissive>0 0 0 1</emissive>
          </material>
        </visual>
        <visual name='alarm_visual_belt_visual'>
          <pose>0 0 0 1.5708 -0 0</pose>
          <geometry>
            <cylinder>
              <radius>0.08</radius>
              <length>0.02</length>
            </cylinder>
          </geometry>
          <material>
            <ambient>1 0 0 1</ambient>
            <diffuse>1 0 0 1</diffuse>
            <specular>0 0 0 0</specular>
            <emissive>0 0 0 1</emissive>
          </material>
        </visual>
        <visual name='alarm_visual_support_visual'>
          <pose>0 0 -0.1 0 -0 0</pose>
          <geometry>
            <box>
              <size>0.05 0.05 0.2</size>
            </box>
          </geometry>
          <material>
            <ambient>0.7 0.7 0 1</ambient>
            <diffuse>0.7 0.7 0 1</diffuse>
            <specular>0 0 0 0</specular>
            <emissive>0 0 0 1</emissive>
          </material>
        </visual>
        <self_collide>0</self_collide>
        <inertial>
          <pose>0 0 0 0 -0 0</pose>
          <inertia>
            <ixx>1</ixx>
            <ixy>0</ixy>
            <ixz>0</ixz>
            <iyy>1</iyy>
            <iyz>0</iyz>
            <izz>1</izz>
          </inertia>
          <mass>1</mass>
        </inertial>
        <enable_wind>0</enable_wind>
        <kinematic>0</kinematic>
      </link>
      <joint name='alarm_visual_joint' type='revolute'>
        <child>alarm_visual_link</child>
        <parent>base_link</parent>
        <axis>
          <xyz>0 0 1</xyz>
          <limit>
            <lower>-1e+16</lower>
            <upper>1e+16</upper>
          </limit>
          <dynamics>
            <spring_reference>0</spring_reference>
            <spring_stiffness>0</spring_stiffness>
          </dynamics>
        </axis>
      </joint>
      <plugin name='gz::sim::systems::JointController' filename='gz-sim-joint-controller-system'>
        <joint_name>right_wheel_joint</joint_name>
        <sub_topic>command/motor_speed</sub_topic>
        <use_actuator_msg>1</use_actuator_msg>
        <actuator_number>0</actuator_number>
        <initial_velocity>0</initial_velocity>
        <use_force_commands>1</use_force_commands>
        <p_gain>5.0</p_gain>
        <i_gain>2.0</i_gain>
        <d_gain>0</d_gain>
        <i_max>1.0</i_max>
        <i_min>-1.0</i_min>
        <cmd_max>1000.0</cmd_max>
        <cmd_min>-1000.0</cmd_min>
        <cmd_offset>0.0</cmd_offset>
      </plugin>
      <plugin name='gz::sim::systems::JointController' filename='gz-sim-joint-controller-system'>
        <joint_name>left_wheel_joint</joint_name>
        <sub_topic>command/motor_speed</sub_topic>
        <use_actuator_msg>1</use_actuator_msg>
        <actuator_number>1</actuator_number>
        <initial_velocity>0</initial_velocity>
        <use_force_commands>1</use_force_commands>
        <p_gain>5.0</p_gain>
        <i_gain>2.0</i_gain>
        <d_gain>0</d_gain>
        <i_max>1.0</i_max>
        <i_min>-1.0</i_min>
        <cmd_max>1000.0</cmd_max>
        <cmd_min>-1000.0</cmd_min>
        <cmd_offset>0.0</cmd_offset>
      </plugin>
      <plugin name='gz::sim::systems::JointController' filename='gz-sim-joint-controller-system'>
        <joint_name>cutter_blades_joint</joint_name>
        <sub_topic>servo_2</sub_topic>
      </plugin>
      <plugin name='gz::sim::systems::JointController' filename='gz-sim-joint-controller-system'>
        <joint_name>engine_visual_joint</joint_name>
        <sub_topic>servo_3</sub_topic>
        <p_gain>10.0</p_gain>
      </plugin>
      <plugin name='gz::sim::systems::JointController' filename='gz-sim-joint-controller-system'>
        <joint_name>alarm_visual_joint</joint_name>
        <sub_topic>servo_4</sub_topic>
        <p_gain>1.0</p_gain>
        <cmd_max>2000.0</cmd_max>
        <cmd_min>1000.0</cmd_min>
        <cmd_offset>0.0</cmd_offset>
      </plugin>
      <plugin name='gz::sim::systems::JointStatePublisher' filename='gz-sim-joint-state-publisher-system'>
        <joint_name>left_wheel_joint</joint_name>
        <joint_name>right_wheel_joint</joint_name>
      </plugin>
      <static>0</static>
    </model>
    <model name='x500_base'>
      <pose>-6.75763 -0.846066 0.24 0 -0 0</pose>
      <self_collide>0</self_collide>
      <static>0</static>
      <link name='base_link'>
        <inertial>
          <mass>2</mass>
          <inertia>
            <ixx>0.0216667</ixx>
            <ixy>0</ixy>
            <ixz>0</ixz>
            <iyy>0.0216667</iyy>
            <iyz>0</iyz>
            <izz>0.04</izz>
          </inertia>
          <pose>0 0 0 0 -0 0</pose>
        </inertial>
        <gravity>1</gravity>
        <velocity_decay/>
        <visual name='base_link_visual'>
          <pose>0 0 0.025 0 -0 -3.14159</pose>
          <geometry>
            <mesh>
              <scale>1 1 1</scale>
              <uri>https://fuel.ignitionrobotics.org/1.0/px4/models/x500_base/1/files/meshes/NXP-HGD-CF.dae</uri>
            </mesh>
          </geometry>
        </visual>
        <visual name='5010_motor_base_0'>
          <pose>0.174 0.174 0.032 0 0 -0.45</pose>
          <geometry>
            <mesh>
              <scale>1 1 1</scale>
              <uri>https://fuel.ignitionrobotics.org/1.0/px4/models/x500_base/1/files/meshes/5010Base.dae</uri>
            </mesh>
          </geometry>
        </visual>
        <visual name='5010_motor_base_1'>
          <pose>-0.174 0.174 0.032 0 0 -0.45</pose>
          <geometry>
            <mesh>
              <scale>1 1 1</scale>
              <uri>https://fuel.ignitionrobotics.org/1.0/px4/models/x500_base/1/files/meshes/5010Base.dae</uri>
            </mesh>
          </geometry>
        </visual>
        <visual name='5010_motor_base_2'>
          <pose>0.174 -0.174 0.032 0 0 -0.45</pose>
          <geometry>
            <mesh>
              <scale>1 1 1</scale>
              <uri>https://fuel.ignitionrobotics.org/1.0/px4/models/x500_base/1/files/meshes/5010Base.dae</uri>
            </mesh>
          </geometry>
        </visual>
        <visual name='5010_motor_base_3'>
          <pose>-0.174 -0.174 0.032 0 0 -0.45</pose>
          <geometry>
            <mesh>
              <scale>1 1 1</scale>
              <uri>https://fuel.ignitionrobotics.org/1.0/px4/models/x500_base/1/files/meshes/5010Base.dae</uri>
            </mesh>
          </geometry>
        </visual>
        <visual name='NXP_FMUK66_FRONT'>
          <pose>0.047 0.001 0.043 1 0 1.57</pose>
          <cast_shadows>0</cast_shadows>
          <geometry>
            <plane>
              <normal>0 0 1</normal>
              <size>0.013 0.007</size>
            </plane>
          </geometry>
          <material>
            <diffuse>1 1 1 1</diffuse>
            <specular>1 1 1 1</specular>
            <pbr>
              <metal>
                <albedo_map>https://fuel.ignitionrobotics.org/1.0/px4/models/x500_base/1/files/materials/textures/nxp.png</albedo_map>
              </metal>
            </pbr>
          </material>
        </visual>
        <visual name='NXP_FMUK66_TOP'>
          <pose>-0.023 0 0.0515 0 0 -1.57</pose>
          <cast_shadows>0</cast_shadows>
          <geometry>
            <plane>
              <normal>0 0 1</normal>
              <size>0.013 0.007</size>
            </plane>
          </geometry>
          <material>
            <diffuse>1 1 1 1</diffuse>
            <specular>1 1 1 1</specular>
            <pbr>
              <metal>
                <albedo_map>https://fuel.ignitionrobotics.org/1.0/px4/models/x500_base/1/files/materials/textures/nxp.png</albedo_map>
              </metal>
            </pbr>
          </material>
        </visual>
        <visual name='RDDRONE_FMUK66_TOP'>
          <pose>-0.03 0 0.0515 0 0 -1.57</pose>
          <cast_shadows>0</cast_shadows>
          <geometry>
            <plane>
              <normal>0 0 1</normal>
              <size>0.032 0.0034</size>
            </plane>
          </geometry>
          <material>
            <diffuse>1 1 1 1</diffuse>
            <specular>1 1 1 1</specular>
            <pbr>
              <metal>
                <albedo_map>https://fuel.ignitionrobotics.org/1.0/px4/models/x500_base/1/files/materials/textures/rd.png</albedo_map>
              </metal>
            </pbr>
          </material>
        </visual>
        <collision name='base_link_collision_0'>
          <pose>0 0 0.007 0 -0 0</pose>
          <geometry>
            <box>
              <size>0.353553 0.353553 0.05</size>
            </box>
          </geometry>
          <surface>
            <contact>
              <ode>
                <min_depth>0.001</min_depth>
                <max_vel>0</max_vel>
              </ode>
            </contact>
            <friction>
              <ode/>
              <torsional>
                <ode/>
              </torsional>
            </friction>
            <bounce/>
          </surface>
          <max_contacts>10</max_contacts>
        </collision>
        <collision name='base_link_collision_1'>
          <pose>0 -0.098 -0.123 -0.35 0 0</pose>
          <geometry>
            <box>
              <size>0.015 0.015 0.21</size>
            </box>
          </geometry>
          <surface>
            <contact>
              <ode>
                <min_depth>0.001</min_depth>
                <max_vel>0</max_vel>
              </ode>
            </contact>
            <friction>
              <ode/>
              <torsional>
                <ode/>
              </torsional>
            </friction>
            <bounce/>
          </surface>
          <max_contacts>10</max_contacts>
        </collision>
        <collision name='base_link_collision_2'>
          <pose>0 0.098 -0.123 0.35 -0 0</pose>
          <geometry>
            <box>
              <size>0.015 0.015 0.21</size>
            </box>
          </geometry>
          <surface>
            <contact>
              <ode>
                <min_depth>0.001</min_depth>
                <max_vel>0</max_vel>
              </ode>
            </contact>
            <friction>
              <ode/>
              <torsional>
                <ode/>
              </torsional>
            </friction>
            <bounce/>
          </surface>
          <max_contacts>10</max_contacts>
        </collision>
        <collision name='base_link_collision_3'>
          <pose>0 -0.132 -0.2195 0 -0 0</pose>
          <geometry>
            <box>
              <size>0.25 0.015 0.015</size>
            </box>
          </geometry>
          <surface>
            <contact>
              <ode>
                <min_depth>0.001</min_depth>
                <max_vel>0</max_vel>
              </ode>
            </contact>
            <friction>
              <ode/>
              <torsional>
                <ode/>
              </torsional>
            </friction>
            <bounce/>
          </surface>
          <max_contacts>10</max_contacts>
        </collision>
        <collision name='base_link_collision_4'>
          <pose>0 0.132 -0.2195 0 -0 0</pose>
          <geometry>
            <box>
              <size>0.25 0.015 0.015</size>
            </box>
          </geometry>
          <surface>
            <contact>
              <ode>
                <min_depth>0.001</min_depth>
                <max_vel>0</max_vel>
              </ode>
            </contact>
            <friction>
              <ode/>
              <torsional>
                <ode/>
              </torsional>
            </friction>
            <bounce/>
          </surface>
          <max_contacts>10</max_contacts>
        </collision>
        <sensor name='air_pressure_sensor' type='air_pressure'>
          <always_on>1</always_on>
          <update_rate>50</update_rate>
          <air_pressure>
            <pressure>
              <noise type='gaussian'>
                <mean>0</mean>
                <stddev>0.01</stddev>
              </noise>
            </pressure>
          </air_pressure>
        </sensor>
        <sensor name='imu_sensor' type='imu'>
          <always_on>1</always_on>
          <update_rate>250</update_rate>
          <imu>
            <angular_velocity>
              <x>
                <noise type='gaussian'>
                  <mean>0</mean>
                  <stddev>0.00018665</stddev>
                  <dynamic_bias_stddev>3.8785e-05</dynamic_bias_stddev>
                  <dynamic_bias_correlation_time>1000</dynamic_bias_correlation_time>
                </noise>
              </x>
              <y>
                <noise type='gaussian'>
                  <mean>0</mean>
                  <stddev>0.00018665</stddev>
                  <dynamic_bias_stddev>3.8785e-05</dynamic_bias_stddev>
                  <dynamic_bias_correlation_time>1000</dynamic_bias_correlation_time>
                </noise>
              </y>
              <z>
                <noise type='gaussian'>
                  <mean>0</mean>
                  <stddev>0.00018665</stddev>
                  <dynamic_bias_stddev>3.8785e-05</dynamic_bias_stddev>
                  <dynamic_bias_correlation_time>1000</dynamic_bias_correlation_time>
                </noise>
              </z>
            </angular_velocity>
            <linear_acceleration>
              <x>
                <noise type='gaussian'>
                  <mean>0</mean>
                  <stddev>0.00186</stddev>
                  <dynamic_bias_stddev>0.006</dynamic_bias_stddev>
                  <dynamic_bias_correlation_time>300</dynamic_bias_correlation_time>
                </noise>
              </x>
              <y>
                <noise type='gaussian'>
                  <mean>0</mean>
                  <stddev>0.00186</stddev>
                  <dynamic_bias_stddev>0.006</dynamic_bias_stddev>
                  <dynamic_bias_correlation_time>300</dynamic_bias_correlation_time>
                </noise>
              </y>
              <z>
                <noise type='gaussian'>
                  <mean>0</mean>
                  <stddev>0.00186</stddev>
                  <dynamic_bias_stddev>0.006</dynamic_bias_stddev>
                  <dynamic_bias_correlation_time>300</dynamic_bias_correlation_time>
                </noise>
              </z>
            </linear_acceleration>
          </imu>
        </sensor>
        <sensor name='navsat_sensor' type='navsat'>
          <always_on>1</always_on>
          <update_rate>30</update_rate>
          <gps/>
        </sensor>
        <self_collide>0</self_collide>
        <enable_wind>0</enable_wind>
        <kinematic>0</kinematic>
      </link>
      <link name='rotor_0'>
        <gravity>1</gravity>
        <self_collide>0</self_collide>
        <velocity_decay/>
        <pose>0.174 -0.174 0.06 0 -0 0</pose>
        <inertial>
          <mass>0.0160769</mass>
          <inertia>
            <ixx>3.84649e-07</ixx>
            <iyy>2.61159e-05</iyy>
            <izz>2.64986e-05</izz>
            <ixy>0</ixy>
            <ixz>0</ixz>
            <iyz>0</iyz>
          </inertia>
          <pose>0 0 0 0 -0 0</pose>
        </inertial>
        <visual name='rotor_0_visual'>
          <pose>-0.022 -0.146385 -0.016 0 -0 0</pose>
          <geometry>
            <mesh>
              <scale>0.846154 0.846154 0.846154</scale>
              <uri>https://fuel.ignitionrobotics.org/1.0/px4/models/x500_base/1/files/meshes/1345_prop_ccw.stl</uri>
            </mesh>
          </geometry>
          <material>
            <script>
              <name>Gazebo/DarkGrey</name>
              <uri>file://media/materials/scripts/gazebo.material</uri>
            </script>
          </material>
        </visual>
        <visual name='rotor_0_visual_motor_bell'>
          <pose>0 0 -0.032 0 -0 0</pose>
          <geometry>
            <mesh>
              <scale>1 1 1</scale>
              <uri>https://fuel.ignitionrobotics.org/1.0/px4/models/x500_base/1/files/meshes/5010Bell.dae</uri>
            </mesh>
          </geometry>
        </visual>
        <collision name='rotor_0_collision'>
          <pose>0 0 0 0 -0 0</pose>
          <geometry>
            <box>
              <size>0.279231 0.016923 0.000846</size>
            </box>
          </geometry>
          <surface>
            <contact>
              <ode>
                <min_depth>0.001</min_depth>
                <max_vel>0</max_vel>
              </ode>
            </contact>
            <friction>
              <ode/>
              <torsional>
                <ode/>
              </torsional>
            </friction>
            <bounce/>
          </surface>
          <max_contacts>10</max_contacts>
        </collision>
        <enable_wind>0</enable_wind>
        <kinematic>0</kinematic>
      </link>
      <joint name='rotor_0_joint' type='revolute'>
        <parent>base_link</parent>
        <child>rotor_0</child>
        <axis>
          <xyz>0 0 1</xyz>
          <limit>
            <lower>-1e+16</lower>
            <upper>1e+16</upper>
          </limit>
          <dynamics>
            <spring_reference>0</spring_reference>
            <spring_stiffness>0</spring_stiffness>
          </dynamics>
        </axis>
      </joint>
      <link name='rotor_1'>
        <gravity>1</gravity>
        <self_collide>0</self_collide>
        <velocity_decay/>
        <pose>-0.174 0.174 0.06 0 -0 0</pose>
        <inertial>
          <mass>0.0160769</mass>
          <inertia>
            <ixx>3.84649e-07</ixx>
            <iyy>2.61159e-05</iyy>
            <izz>2.64986e-05</izz>
            <ixy>0</ixy>
            <ixz>0</ixz>
            <iyz>0</iyz>
          </inertia>
          <pose>0 0 0 0 -0 0</pose>
        </inertial>
        <visual name='rotor_1_visual'>
          <pose>-0.022 -0.146385 -0.016 0 -0 0</pose>
          <geometry>
            <mesh>
              <scale>0.846154 0.846154 0.846154</scale>
              <uri>https://fuel.ignitionrobotics.org/1.0/px4/models/x500_base/1/files/meshes/1345_prop_ccw.stl</uri>
            </mesh>
          </geometry>
          <material>
            <script>
              <name>Gazebo/DarkGrey</name>
              <uri>file://media/materials/scripts/gazebo.material</uri>
            </script>
          </material>
        </visual>
        <visual name='rotor_1_visual_motor_top'>
          <pose>0 0 -0.032 0 -0 0</pose>
          <geometry>
            <mesh>
              <scale>1 1 1</scale>
              <uri>https://fuel.ignitionrobotics.org/1.0/px4/models/x500_base/1/files/meshes/5010Bell.dae</uri>
            </mesh>
          </geometry>
        </visual>
        <collision name='rotor_1_collision'>
          <pose>0 0 0 0 -0 0</pose>
          <geometry>
            <box>
              <size>0.279231 0.016923 0.000846</size>
            </box>
          </geometry>
          <surface>
            <contact>
              <ode>
                <min_depth>0.001</min_depth>
                <max_vel>0</max_vel>
              </ode>
            </contact>
            <friction>
              <ode/>
              <torsional>
                <ode/>
              </torsional>
            </friction>
            <bounce/>
          </surface>
          <max_contacts>10</max_contacts>
        </collision>
        <enable_wind>0</enable_wind>
        <kinematic>0</kinematic>
      </link>
      <joint name='rotor_1_joint' type='revolute'>
        <parent>base_link</parent>
        <child>rotor_1</child>
        <axis>
          <xyz>0 0 1</xyz>
          <limit>
            <lower>-1e+16</lower>
            <upper>1e+16</upper>
          </limit>
          <dynamics>
            <spring_reference>0</spring_reference>
            <spring_stiffness>0</spring_stiffness>
          </dynamics>
        </axis>
      </joint>
      <link name='rotor_2'>
        <gravity>1</gravity>
        <self_collide>0</self_collide>
        <velocity_decay/>
        <pose>0.174 0.174 0.06 0 -0 0</pose>
        <inertial>
          <mass>0.0160769</mass>
          <inertia>
            <ixx>3.84649e-07</ixx>
            <iyy>2.61159e-05</iyy>
            <izz>2.64986e-05</izz>
            <ixy>0</ixy>
            <ixz>0</ixz>
            <iyz>0</iyz>
          </inertia>
          <pose>0 0 0 0 -0 0</pose>
        </inertial>
        <visual name='rotor_2_visual'>
          <pose>-0.022 -0.146385 -0.016 0 -0 0</pose>
          <geometry>
            <mesh>
              <scale>0.846154 0.846154 0.846154</scale>
              <uri>https://fuel.ignitionrobotics.org/1.0/px4/models/x500_base/1/files/meshes/1345_prop_cw.stl</uri>
            </mesh>
          </geometry>
          <material>
            <script>
              <name>Gazebo/DarkGrey</name>
              <uri>file://media/materials/scripts/gazebo.material</uri>
            </script>
          </material>
        </visual>
        <visual name='rotor_2_visual_motor_top'>
          <pose>0 0 -0.032 0 -0 0</pose>
          <geometry>
            <mesh>
              <scale>1 1 1</scale>
              <uri>https://fuel.ignitionrobotics.org/1.0/px4/models/x500_base/1/files/meshes/5010Bell.dae</uri>
            </mesh>
          </geometry>
        </visual>
        <collision name='rotor_2_collision'>
          <pose>0 0 0 0 -0 0</pose>
          <geometry>
            <box>
              <size>0.279231 0.016923 0.000846</size>
            </box>
          </geometry>
          <surface>
            <contact>
              <ode>
                <min_depth>0.001</min_depth>
                <max_vel>0</max_vel>
              </ode>
            </contact>
            <friction>
              <ode/>
              <torsional>
                <ode/>
              </torsional>
            </friction>
            <bounce/>
          </surface>
          <max_contacts>10</max_contacts>
        </collision>
        <enable_wind>0</enable_wind>
        <kinematic>0</kinematic>
      </link>
      <joint name='rotor_2_joint' type='revolute'>
        <parent>base_link</parent>
        <child>rotor_2</child>
        <axis>
          <xyz>0 0 1</xyz>
          <limit>
            <lower>-1e+16</lower>
            <upper>1e+16</upper>
          </limit>
          <dynamics>
            <spring_reference>0</spring_reference>
            <spring_stiffness>0</spring_stiffness>
          </dynamics>
        </axis>
      </joint>
      <link name='rotor_3'>
        <gravity>1</gravity>
        <self_collide>0</self_collide>
        <velocity_decay/>
        <pose>-0.174 -0.174 0.06 0 -0 0</pose>
        <inertial>
          <mass>0.0160769</mass>
          <inertia>
            <ixx>3.84649e-07</ixx>
            <iyy>2.61159e-05</iyy>
            <izz>2.64986e-05</izz>
            <ixy>0</ixy>
            <ixz>0</ixz>
            <iyz>0</iyz>
          </inertia>
          <pose>0 0 0 0 -0 0</pose>
        </inertial>
        <visual name='rotor_3_visual'>
          <pose>-0.022 -0.146385 -0.016 0 -0 0</pose>
          <geometry>
            <mesh>
              <scale>0.846154 0.846154 0.846154</scale>
              <uri>https://fuel.ignitionrobotics.org/1.0/px4/models/x500_base/1/files/meshes/1345_prop_cw.stl</uri>
            </mesh>
          </geometry>
          <material>
            <script>
              <name>Gazebo/DarkGrey</name>
              <uri>file://media/materials/scripts/gazebo.material</uri>
            </script>
          </material>
        </visual>
        <visual name='rotor_3_visual_motor_top'>
          <pose>0 0 -0.032 0 -0 0</pose>
          <geometry>
            <mesh>
              <scale>1 1 1</scale>
              <uri>https://fuel.ignitionrobotics.org/1.0/px4/models/x500_base/1/files/meshes/5010Bell.dae</uri>
            </mesh>
          </geometry>
        </visual>
        <collision name='rotor_3_collision'>
          <pose>0 0 0 0 -0 0</pose>
          <geometry>
            <box>
              <size>0.279231 0.016923 0.000846</size>
            </box>
          </geometry>
          <surface>
            <contact>
              <ode>
                <min_depth>0.001</min_depth>
                <max_vel>0</max_vel>
              </ode>
            </contact>
            <friction>
              <ode/>
              <torsional>
                <ode/>
              </torsional>
            </friction>
            <bounce/>
          </surface>
          <max_contacts>10</max_contacts>
        </collision>
        <enable_wind>0</enable_wind>
        <kinematic>0</kinematic>
      </link>
      <joint name='rotor_3_joint' type='revolute'>
        <parent>base_link</parent>
        <child>rotor_3</child>
        <axis>
          <xyz>0 0 1</xyz>
          <limit>
            <lower>-1e+16</lower>
            <upper>1e+16</upper>
          </limit>
          <dynamics>
            <spring_reference>0</spring_reference>
            <spring_stiffness>0</spring_stiffness>
          </dynamics>
        </axis>
      </joint>
    </model>
    <model name='plane'>
      <pose>-1.97088 -2.37934 0.246 0 -0 0</pose>
      <link name='base_link'>
        <pose>0 0 0 0 -0 0</pose>
        <inertial>
          <pose>0 0 0 0 -0 0</pose>
          <mass>1</mass>
          <inertia>
            <ixx>0.197563</ixx>
            <ixy>0</ixy>
            <ixz>0</ixz>
            <iyy>0.145893</iyy>
            <iyz>0</iyz>
            <izz>0.1477</izz>
          </inertia>
        </inertial>
        <collision name='base_link_collision'>
          <pose>0 0 -0.07 0 -0 0</pose>
          <geometry>
            <box>
              <size>0.47 0.47 0.11</size>
            </box>
          </geometry>
          <surface>
            <contact>
              <ode>
                <max_vel>10</max_vel>
                <min_depth>0.01</min_depth>
              </ode>
            </contact>
            <friction>
              <ode/>
              <torsional>
                <ode/>
              </torsional>
            </friction>
            <bounce/>
          </surface>
          <max_contacts>10</max_contacts>
        </collision>
        <visual name='base_link_visual'>
          <pose>0.07 0 -0.08 0 -0 0</pose>
          <geometry>
            <mesh>
              <scale>0.1 0.1 0.1</scale>
              <uri>https://fuel.ignitionrobotics.org/1.0/px4/models/advanced plane/1/files/meshes/body.dae</uri>
            </mesh>
          </geometry>
          <material>
            <ambient>0.175 0.175 0.175 1</ambient>
            <diffuse>0.175 0.175 0.175 1</diffuse>
          </material>
        </visual>
        <gravity>1</gravity>
        <velocity_decay/>
        <self_collide>0</self_collide>
        <sensor name='imu_sensor' type='imu'>
          <always_on>1</always_on>
          <update_rate>250</update_rate>
          <imu/>
        </sensor>
        <sensor name='air_pressure_sensor' type='air_pressure'>
          <always_on>1</always_on>
          <update_rate>50</update_rate>
          <air_pressure>
            <pressure>
              <noise type='gaussian'>
                <mean>0</mean>
                <stddev>0.01</stddev>
              </noise>
            </pressure>
          </air_pressure>
        </sensor>
        <enable_wind>0</enable_wind>
        <kinematic>0</kinematic>
      </link>
      <link name='rotor_puller'>
        <pose>0.3 0 0 0 1.57 0</pose>
        <inertial>
          <pose>0 0 0 0 -0 0</pose>
          <mass>0.005</mass>
          <inertia>
            <ixx>9.75e-07</ixx>
            <ixy>0</ixy>
            <ixz>0</ixz>
            <iyy>0.000166704</iyy>
            <iyz>0</iyz>
            <izz>0.000167604</izz>
          </inertia>
        </inertial>
        <collision name='rotor_puller_collision'>
          <pose>0 0 0 0 -0 0</pose>
          <geometry>
            <cylinder>
              <length>0.005</length>
              <radius>0.1</radius>
            </cylinder>
          </geometry>
          <surface>
            <contact>
              <ode/>
            </contact>
            <friction>
              <ode/>
              <torsional>
                <ode/>
              </torsional>
            </friction>
            <bounce/>
          </surface>
          <max_contacts>10</max_contacts>
        </collision>
        <visual name='rotor_puller_visual'>
          <pose>0 0 -0.09 0 -0 0</pose>
          <geometry>
            <mesh>
              <scale>1 1 1</scale>
              <uri>https://fuel.ignitionrobotics.org/1.0/px4/models/advanced plane/1/files/meshes/iris_prop_ccw.dae</uri>
            </mesh>
          </geometry>
          <material>
            <ambient>0.175 0.175 0.175 1</ambient>
            <diffuse>0.175 0.175 0.175 1</diffuse>
          </material>
        </visual>
        <gravity>1</gravity>
        <velocity_decay/>
        <self_collide>0</self_collide>
        <enable_wind>0</enable_wind>
        <kinematic>0</kinematic>
      </link>
      <joint name='rotor_puller_joint' type='revolute'>
        <child>rotor_puller</child>
        <parent>base_link</parent>
        <axis>
          <xyz expressed_in='__model__'>1 0 0</xyz>
          <limit>
            <lower>-1e+16</lower>
            <upper>1e+16</upper>
          </limit>
          <dynamics>
            <spring_reference>0</spring_reference>
            <spring_stiffness>0</spring_stiffness>
          </dynamics>
        </axis>
      </joint>
      <link name='left_elevon'>
        <inertial>
          <mass>1e-08</mass>
          <inertia>
            <ixx>1e-06</ixx>
            <ixy>0</ixy>
            <iyy>1e-06</iyy>
            <ixz>0</ixz>
            <iyz>0</iyz>
            <izz>1e-06</izz>
          </inertia>
          <pose>0 0.3 0 0 -0 0</pose>
        </inertial>
        <visual name='left_elevon_visual'>
          <pose>0.07 0 -0.08 0 -0 0</pose>
          <geometry>
            <mesh>
              <scale>0.1 0.1 0.1</scale>
              <uri>https://fuel.ignitionrobotics.org/1.0/px4/models/advanced plane/1/files/meshes/left_aileron.dae</uri>
            </mesh>
          </geometry>
          <material>
            <ambient>1 0 0 1</ambient>
            <diffuse>1 0 0 1</diffuse>
          </material>
        </visual>
        <self_collide>0</self_collide>
        <enable_wind>0</enable_wind>
        <kinematic>0</kinematic>
      </link>
      <link name='right_elevon'>
        <inertial>
          <mass>1e-08</mass>
          <inertia>
            <ixx>1e-06</ixx>
            <ixy>0</ixy>
            <iyy>1e-06</iyy>
            <ixz>0</ixz>
            <iyz>0</iyz>
            <izz>1e-06</izz>
          </inertia>
          <pose>0 -0.3 0 0 -0 0</pose>
        </inertial>
        <visual name='right_elevon_visual'>
          <pose>0.07 0 -0.08 0 -0 0</pose>
          <geometry>
            <mesh>
              <scale>0.1 0.1 0.1</scale>
              <uri>https://fuel.ignitionrobotics.org/1.0/px4/models/advanced plane/1/files/meshes/right_aileron.dae</uri>
            </mesh>
          </geometry>
          <material>
            <ambient>1 0 0 1</ambient>
            <diffuse>1 0 0 1</diffuse>
          </material>
        </visual>
        <self_collide>0</self_collide>
        <enable_wind>0</enable_wind>
        <kinematic>0</kinematic>
      </link>
      <link name='left_flap'>
        <inertial>
          <mass>1e-08</mass>
          <inertia>
            <ixx>1e-06</ixx>
            <ixy>0</ixy>
            <iyy>1e-06</iyy>
            <ixz>0</ixz>
            <iyz>0</iyz>
            <izz>1e-06</izz>
          </inertia>
          <pose>0 0.15 0 0 -0 0</pose>
        </inertial>
        <visual name='left_flap_visual'>
          <pose>0.07 0 -0.08 0 -0 0</pose>
          <geometry>
            <mesh>
              <scale>0.1 0.1 0.1</scale>
              <uri>https://fuel.ignitionrobotics.org/1.0/px4/models/advanced plane/1/files/meshes/left_flap.dae</uri>
            </mesh>
          </geometry>
          <material>
            <ambient>1 0 0 1</ambient>
            <diffuse>1 0 0 1</diffuse>
          </material>
        </visual>
        <self_collide>0</self_collide>
        <enable_wind>0</enable_wind>
        <kinematic>0</kinematic>
      </link>
      <link name='right_flap'>
        <inertial>
          <mass>1e-08</mass>
          <inertia>
            <ixx>1e-06</ixx>
            <ixy>0</ixy>
            <iyy>1e-06</iyy>
            <ixz>0</ixz>
            <iyz>0</iyz>
            <izz>1e-06</izz>
          </inertia>
          <pose>0 -0.15 0 0 -0 0</pose>
        </inertial>
        <visual name='right_flap_visual'>
          <pose>0.07 0 -0.08 0 -0 0</pose>
          <geometry>
            <mesh>
              <scale>0.1 0.1 0.1</scale>
              <uri>https://fuel.ignitionrobotics.org/1.0/px4/models/advanced plane/1/files/meshes/right_flap.dae</uri>
            </mesh>
          </geometry>
          <material>
            <ambient>1 0 0 1</ambient>
            <diffuse>1 0 0 1</diffuse>
          </material>
        </visual>
        <self_collide>0</self_collide>
        <enable_wind>0</enable_wind>
        <kinematic>0</kinematic>
      </link>
      <link name='elevator'>
        <inertial>
          <mass>1e-08</mass>
          <inertia>
            <ixx>1e-06</ixx>
            <ixy>0</ixy>
            <iyy>1e-06</iyy>
            <ixz>0</ixz>
            <iyz>0</iyz>
            <izz>1e-06</izz>
          </inertia>
          <pose>-0.5 0 0 0 -0 0</pose>
        </inertial>
        <visual name='elevator_visual'>
          <pose>0.07 0 -0.08 0 -0 0</pose>
          <geometry>
            <mesh>
              <scale>0.1 0.1 0.1</scale>
              <uri>https://fuel.ignitionrobotics.org/1.0/px4/models/advanced plane/1/files/meshes/elevators.dae</uri>
            </mesh>
          </geometry>
          <material>
            <ambient>1 0 0 1</ambient>
            <diffuse>1 0 0 1</diffuse>
          </material>
        </visual>
        <self_collide>0</self_collide>
        <enable_wind>0</enable_wind>
        <kinematic>0</kinematic>
      </link>
      <link name='rudder'>
        <inertial>
          <mass>1e-08</mass>
          <inertia>
            <ixx>1e-06</ixx>
            <ixy>0</ixy>
            <iyy>1e-06</iyy>
            <ixz>0</ixz>
            <iyz>0</iyz>
            <izz>1e-06</izz>
          </inertia>
          <pose>-0.5 0 0.05 0 -0 0</pose>
        </inertial>
        <visual name='rudder_visual'>
          <pose>0.07 0 -0.08 0 -0 0</pose>
          <geometry>
            <mesh>
              <scale>0.1 0.1 0.1</scale>
              <uri>https://fuel.ignitionrobotics.org/1.0/px4/models/advanced plane/1/files/meshes/rudder.dae</uri>
            </mesh>
          </geometry>
          <material>
            <ambient>1 0 0 1</ambient>
            <diffuse>1 0 0 1</diffuse>
          </material>
        </visual>
        <self_collide>0</self_collide>
        <enable_wind>0</enable_wind>
        <kinematic>0</kinematic>
      </link>
      <joint name='servo_0' type='revolute'>
        <parent>base_link</parent>
        <child>left_elevon</child>
        <pose>-0.07 0.4 0.08 0 -0 0</pose>
        <axis>
          <xyz>0 1 0</xyz>
          <limit>
            <lower>-0.53</lower>
            <upper>0.53</upper>
          </limit>
          <dynamics>
            <damping>1</damping>
            <spring_reference>0</spring_reference>
            <spring_stiffness>0</spring_stiffness>
          </dynamics>
        </axis>
        <physics>
          <ode>
            <implicit_spring_damper>1</implicit_spring_damper>
            <limit>
              <cfm>0</cfm>
              <erp>0.2</erp>
            </limit>
          </ode>
        </physics>
      </joint>
      <plugin name='gz::sim::systems::JointPositionController' filename='gz-sim-joint-position-controller-system'>
        <joint_name>servo_0</joint_name>
        <sub_topic>servo_0</sub_topic>
        <p_gain>10</p_gain>
        <i_gain>0</i_gain>
        <d_gain>0</d_gain>
      </plugin>
      <joint name='servo_1' type='revolute'>
        <parent>base_link</parent>
        <child>right_elevon</child>
        <pose>-0.07 -0.4 0.08 0 -0 0</pose>
        <axis>
          <xyz>0 1 0</xyz>
          <limit>
            <lower>-0.53</lower>
            <upper>0.53</upper>
          </limit>
          <dynamics>
            <damping>1</damping>
            <spring_reference>0</spring_reference>
            <spring_stiffness>0</spring_stiffness>
          </dynamics>
        </axis>
        <physics>
          <ode>
            <implicit_spring_damper>1</implicit_spring_damper>
            <limit>
              <cfm>0</cfm>
              <erp>0.2</erp>
            </limit>
          </ode>
        </physics>
      </joint>
      <plugin name='gz::sim::systems::JointPositionController' filename='gz-sim-joint-position-controller-system'>
        <joint_name>servo_1</joint_name>
        <sub_topic>servo_1</sub_topic>
        <p_gain>10</p_gain>
        <i_gain>0</i_gain>
        <d_gain>0</d_gain>
      </plugin>
      <joint name='servo_4' type='revolute'>
        <parent>base_link</parent>
        <child>left_flap</child>
        <pose>-0.07 0.2 0.08 0 -0 0</pose>
        <axis>
          <xyz>0 1 0</xyz>
          <limit>
            <lower>-0.53</lower>
            <upper>0.53</upper>
          </limit>
          <dynamics>
            <damping>1</damping>
            <spring_reference>0</spring_reference>
            <spring_stiffness>0</spring_stiffness>
          </dynamics>
        </axis>
        <physics>
          <ode>
            <implicit_spring_damper>1</implicit_spring_damper>
            <limit>
              <cfm>0</cfm>
              <erp>0.2</erp>
            </limit>
          </ode>
        </physics>
      </joint>
      <plugin name='gz::sim::systems::JointPositionController' filename='gz-sim-joint-position-controller-system'>
        <joint_name>servo_4</joint_name>
        <sub_topic>servo_4</sub_topic>
        <p_gain>10</p_gain>
        <i_gain>0</i_gain>
        <d_gain>0</d_gain>
      </plugin>
      <joint name='servo_5' type='revolute'>
        <parent>base_link</parent>
        <child>right_flap</child>
        <pose>-0.07 -0.2 0.08 0 -0 0</pose>
        <axis>
          <xyz>0 1 0</xyz>
          <limit>
            <lower>-0.53</lower>
            <upper>0.53</upper>
          </limit>
          <dynamics>
            <damping>1</damping>
            <spring_reference>0</spring_reference>
            <spring_stiffness>0</spring_stiffness>
          </dynamics>
        </axis>
        <physics>
          <ode>
            <implicit_spring_damper>1</implicit_spring_damper>
            <limit>
              <cfm>0</cfm>
              <erp>0.2</erp>
            </limit>
          </ode>
        </physics>
      </joint>
      <plugin name='gz::sim::systems::JointPositionController' filename='gz-sim-joint-position-controller-system'>
        <joint_name>servo_5</joint_name>
        <sub_topic>servo_5</sub_topic>
        <p_gain>10</p_gain>
        <i_gain>0</i_gain>
        <d_gain>0</d_gain>
      </plugin>
      <joint name='servo_2' type='revolute'>
        <parent>base_link</parent>
        <child>elevator</child>
        <pose>-0.5 0 0 0 -0 0</pose>
        <axis>
          <xyz>0 1 0</xyz>
          <limit>
            <lower>-0.53</lower>
            <upper>0.53</upper>
          </limit>
          <dynamics>
            <damping>1</damping>
            <spring_reference>0</spring_reference>
            <spring_stiffness>0</spring_stiffness>
          </dynamics>
        </axis>
        <physics>
          <ode>
            <implicit_spring_damper>1</implicit_spring_damper>
            <limit>
              <cfm>0</cfm>
              <erp>0.2</erp>
            </limit>
          </ode>
        </physics>
      </joint>
      <plugin name='gz::sim::systems::JointPositionController' filename='gz-sim-joint-position-controller-system'>
        <joint_name>servo_2</joint_name>
        <sub_topic>servo_2</sub_topic>
        <p_gain>10</p_gain>
        <i_gain>0</i_gain>
        <d_gain>0</d_gain>
      </plugin>
      <joint name='servo_3' type='revolute'>
        <parent>base_link</parent>
        <child>rudder</child>
        <pose>-0.5 0 0.05 0 -0 0</pose>
        <axis>
          <xyz>0 0 1</xyz>
          <limit>
            <lower>-0.53</lower>
            <upper>0.53</upper>
          </limit>
          <dynamics>
            <damping>1</damping>
            <spring_reference>0</spring_reference>
            <spring_stiffness>0</spring_stiffness>
          </dynamics>
        </axis>
        <physics>
          <ode>
            <implicit_spring_damper>1</implicit_spring_damper>
            <limit>
              <cfm>0</cfm>
              <erp>0.2</erp>
            </limit>
          </ode>
        </physics>
      </joint>
      <plugin name='gz::sim::systems::JointPositionController' filename='gz-sim-joint-position-controller-system'>
        <joint_name>servo_3</joint_name>
        <sub_topic>servo_3</sub_topic>
        <p_gain>10</p_gain>
        <i_gain>0</i_gain>
        <d_gain>0</d_gain>
      </plugin>
      <plugin name='gz::sim::systems::AdvancedLiftDrag' filename='gz-sim-advanced-lift-drag-system'>
        <a0>0.0</a0>
        <CL0>0.15188</CL0>
        <AR>6.5</AR>
        <eff>0.97</eff>
        <CLa>5.015</CLa>
        <CD0>0.029</CD0>
        <Cem0>0.075</Cem0>
        <Cema>-0.463966</Cema>
        <CYb>-0.258244</CYb>
        <Cellb>-0.039250</Cellb>
        <Cenb>0.100826</Cenb>
        <CDp>0.0</CDp>
        <CYp>0.065861</CYp>
        <CLp>0.0</CLp>
        <Cellp>-0.487407</Cellp>
        <Cemp>0.0</Cemp>
        <Cenp>-0.040416</Cenp>
        <CDq>0.055166</CDq>
        <CYq>0.0</CYq>
        <CLq>7.971792</CLq>
        <Cellq>0.0</Cellq>
        <Cemq>-12.140140</Cemq>
        <Cenq>0.0</Cenq>
        <CDr>0.0</CDr>
        <CYr>0.230299</CYr>
        <CLr>0.0</CLr>
        <Cellr>0.078165</Cellr>
        <Cemr>0.0</Cemr>
        <Cenr>-0.089947</Cenr>
        <alpha_stall>0.3391428111</alpha_stall>
        <CLa_stall>-3.85</CLa_stall>
        <CDa_stall>-0.9233984055</CDa_stall>
        <Cema_stall>0</Cema_stall>
        <cp>-0.12 0.0 0.0</cp>
        <area>0.34</area>
        <mac>0.22</mac>
        <air_density>1.2041</air_density>
        <forward>1 0 0</forward>
        <upward>0 0 1</upward>
        <link_name>base_link</link_name>
        <num_ctrl_surfaces>4</num_ctrl_surfaces>
        <control_surface>
          <name>servo_0</name>
          <index>0</index>
          <direction>1</direction>
          <CD_ctrl>-0.000059</CD_ctrl>
          <CY_ctrl>0.000171</CY_ctrl>
          <CL_ctrl>-0.011940</CL_ctrl>
          <Cell_ctrl>-0.003331</Cell_ctrl>
          <Cem_ctrl>0.001498</Cem_ctrl>
          <Cen_ctrl>-0.000057</Cen_ctrl>
        </control_surface>
        <control_surface>
          <name>servo_1</name>
          <direction>1</direction>
          <index>1</index>
          <CD_ctrl>-0.000059</CD_ctrl>
          <CY_ctrl>-0.000171</CY_ctrl>
          <CL_ctrl>-0.011940</CL_ctrl>
          <Cell_ctrl>0.003331</Cell_ctrl>
          <Cem_ctrl>0.001498</Cem_ctrl>
          <Cen_ctrl>0.000057</Cen_ctrl>
        </control_surface>
        <control_surface>
          <name>servo_2</name>
          <direction>-1</direction>
          <index>2</index>
          <CD_ctrl>0.000274</CD_ctrl>
          <CY_ctrl>0</CY_ctrl>
          <CL_ctrl>0.010696</CL_ctrl>
          <Cell_ctrl>0.0</Cell_ctrl>
          <Cem_ctrl>-0.025798</Cem_ctrl>
          <Cen_ctrl>0.0</Cen_ctrl>
        </control_surface>
        <control_surface>
          <name>servo_3</name>
          <direction>1</direction>
          <index>3</index>
          <CD_ctrl>0.0</CD_ctrl>
          <CY_ctrl>-0.003913</CY_ctrl>
          <CL_ctrl>0.0</CL_ctrl>
          <Cell_ctrl>-0.000257</Cell_ctrl>
          <Cem_ctrl>0.0</Cem_ctrl>
          <Cen_ctrl>0.001613</Cen_ctrl>
        </control_surface>
      </plugin>
      <plugin name='gz::sim::systems::MulticopterMotorModel' filename='gz-sim-multicopter-motor-model-system'>
        <jointName>rotor_puller_joint</jointName>
        <linkName>rotor_puller</linkName>
        <turningDirection>cw</turningDirection>
        <timeConstantUp>0.0125</timeConstantUp>
        <timeConstantDown>0.025</timeConstantDown>
        <maxRotVelocity>3500</maxRotVelocity>
        <motorConstant>8.54858e-06</motorConstant>
        <momentConstant>0.01</momentConstant>
        <commandSubTopic>command/motor_speed</commandSubTopic>
        <motorNumber>0</motorNumber>
        <rotorDragCoefficient>8.06428e-05</rotorDragCoefficient>
        <rollingMomentCoefficient>1e-06</rollingMomentCoefficient>
        <rotorVelocitySlowdownSim>10</rotorVelocitySlowdownSim>
        <motorType>velocity</motorType>
      </plugin>
    </model>
    <model name='simple_arm'>
      <link name='arm_base'>
        <inertial>
          <pose>0 0 0.00099 0 -0 0</pose>
          <inertia>
            <ixx>8.418</ixx>
            <ixy>0</ixy>
            <ixz>0</ixz>
            <iyy>8.418</iyy>
            <iyz>0</iyz>
            <izz>16.67</izz>
          </inertia>
          <mass>101</mass>
        </inertial>
        <collision name='arm_base_geom'>
          <pose>0 0 0.05 0 -0 0</pose>
          <geometry>
            <box>
              <size>1 1 0.1</size>
            </box>
          </geometry>
          <max_contacts>10</max_contacts>
          <surface>
            <contact>
              <ode/>
            </contact>
            <bounce/>
            <friction>
              <torsional>
                <ode/>
              </torsional>
              <ode/>
            </friction>
          </surface>
        </collision>
        <visual name='arm_base_geom_visual'>
          <pose>0 0 0.05 0 -0 0</pose>
          <geometry>
            <box>
              <size>1 1 0.1</size>
            </box>
          </geometry>
          <material>
            <ambient>0 0 1 1</ambient>
            <diffuse>0 0 1 1</diffuse>
            <specular>0.01 0.01 0.01 1</specular>
          </material>
        </visual>
        <collision name='arm_base_geom_arm_trunk'>
          <pose>0 0 0.6 0 -0 0</pose>
          <geometry>
            <cylinder>
              <radius>0.05</radius>
              <length>1</length>
            </cylinder>
          </geometry>
          <max_contacts>10</max_contacts>
          <surface>
            <contact>
              <ode/>
            </contact>
            <bounce/>
            <friction>
              <torsional>
                <ode/>
              </torsional>
              <ode/>
            </friction>
          </surface>
        </collision>
        <visual name='arm_base_geom_arm_trunk_visual'>
          <pose>0 0 0.6 0 -0 0</pose>
          <geometry>
            <cylinder>
              <radius>0.05</radius>
              <length>1</length>
            </cylinder>
          </geometry>
          <material>
            <ambient>1 0 0 1</ambient>
            <diffuse>1 0 0 1</diffuse>
            <specular>0.01 0.01 0.01 1</specular>
          </material>
        </visual>
        <self_collide>0</self_collide>
        <enable_wind>0</enable_wind>
        <kinematic>0</kinematic>
      </link>
      <link name='arm_shoulder_pan'>
        <pose>0 0 1.1 0 -0 0</pose>
        <inertial>
          <pose>0.045455 0 0 0 -0 0</pose>
          <inertia>
            <ixx>0.011</ixx>
            <ixy>0</ixy>
            <ixz>0</ixz>
            <iyy>0.0225</iyy>
            <iyz>0</iyz>
            <izz>0.0135</izz>
          </inertia>
          <mass>1.1</mass>
        </inertial>
        <collision name='arm_shoulder_pan_geom'>
          <pose>0 0 0.05 0 -0 0</pose>
          <geometry>
            <cylinder>
              <radius>0.05</radius>
              <length>0.1</length>
            </cylinder>
          </geometry>
          <max_contacts>10</max_contacts>
          <surface>
            <contact>
              <ode/>
            </contact>
            <bounce/>
            <friction>
              <torsional>
                <ode/>
              </torsional>
              <ode/>
            </friction>
          </surface>
        </collision>
        <visual name='arm_shoulder_pan_geom_visual'>
          <pose>0 0 0.05 0 -0 0</pose>
          <geometry>
            <cylinder>
              <radius>0.05</radius>
              <length>0.1</length>
            </cylinder>
          </geometry>
          <material>
            <ambient>1 1 0 1</ambient>
            <diffuse>1 1 0 1</diffuse>
            <specular>0.01 0.01 0.01 1</specular>
          </material>
        </visual>
        <collision name='arm_shoulder_pan_geom_arm_shoulder'>
          <pose>0.55 0 0.05 0 -0 0</pose>
          <geometry>
            <box>
              <size>1 0.05 0.1</size>
            </box>
          </geometry>
          <max_contacts>10</max_contacts>
          <surface>
            <contact>
              <ode/>
            </contact>
            <bounce/>
            <friction>
              <torsional>
                <ode/>
              </torsional>
              <ode/>
            </friction>
          </surface>
        </collision>
        <visual name='arm_shoulder_pan_geom_arm_shoulder_visual'>
          <pose>0.55 0 0.05 0 -0 0</pose>
          <geometry>
            <box>
              <size>1 0.05 0.1</size>
            </box>
          </geometry>
          <material>
            <ambient>1 1 0 1</ambient>
            <diffuse>1 1 0 1</diffuse>
            <specular>0.01 0.01 0.01 1</specular>
          </material>
        </visual>
        <self_collide>0</self_collide>
        <enable_wind>0</enable_wind>
        <kinematic>0</kinematic>
      </link>
      <link name='arm_elbow_pan'>
        <pose>1.05 0 1.1 0 -0 0</pose>
        <inertial>
          <pose>0.0875 0 0.083333 0 -0 0</pose>
          <inertia>
            <ixx>0.031</ixx>
            <ixy>0</ixy>
            <ixz>0.005</ixz>
            <iyy>0.07275</iyy>
            <iyz>0</iyz>
            <izz>0.04475</izz>
          </inertia>
          <mass>1.2</mass>
        </inertial>
        <collision name='arm_elbow_pan_geom'>
          <pose>0 0 0.1 0 -0 0</pose>
          <geometry>
            <cylinder>
              <radius>0.05</radius>
              <length>0.2</length>
            </cylinder>
          </geometry>
          <max_contacts>10</max_contacts>
          <surface>
            <contact>
              <ode/>
            </contact>
            <bounce/>
            <friction>
              <torsional>
                <ode/>
              </torsional>
              <ode/>
            </friction>
          </surface>
        </collision>
        <visual name='arm_elbow_pan_geom_visual'>
          <pose>0 0 0.1 0 -0 0</pose>
          <geometry>
            <cylinder>
              <radius>0.05</radius>
              <length>0.2</length>
            </cylinder>
          </geometry>
          <material>
            <ambient>1 0 0 1</ambient>
            <diffuse>1 0 0 1</diffuse>
            <specular>0.01 0.01 0.01 1</specular>
          </material>
        </visual>
        <collision name='arm_elbow_pan_geom_arm_elbow'>
          <pose>0.3 0 0.15 0 -0 0</pose>
          <geometry>
            <box>
              <size>0.5 0.03 0.1</size>
            </box>
          </geometry>
          <max_contacts>10</max_contacts>
          <surface>
            <contact>
              <ode/>
            </contact>
            <bounce/>
            <friction>
              <torsional>
                <ode/>
              </torsional>
              <ode/>
            </friction>
          </surface>
        </collision>
        <visual name='arm_elbow_pan_geom_arm_elbow_visual'>
          <pose>0.3 0 0.15 0 -0 0</pose>
          <geometry>
            <box>
              <size>0.5 0.03 0.1</size>
            </box>
          </geometry>
          <material>
            <ambient>1 1 0 1</ambient>
            <diffuse>1 1 0 1</diffuse>
            <specular>0.01 0.01 0.01 1</specular>
          </material>
        </visual>
        <collision name='arm_elbow_pan_geom_arm_wrist'>
          <pose>0.55 0 0.15 0 -0 0</pose>
          <geometry>
            <cylinder>
              <radius>0.05</radius>
              <length>0.3</length>
            </cylinder>
          </geometry>
          <max_contacts>10</max_contacts>
          <surface>
            <contact>
              <ode/>
            </contact>
            <bounce/>
            <friction>
              <torsional>
                <ode/>
              </torsional>
              <ode/>
            </friction>
          </surface>
        </collision>
        <visual name='arm_elbow_pan_geom_arm_wrist_visual'>
          <pose>0.55 0 0.15 0 -0 0</pose>
          <geometry>
            <cylinder>
              <radius>0.05</radius>
              <length>0.3</length>
            </cylinder>
          </geometry>
          <material>
            <ambient>1 0 0 1</ambient>
            <diffuse>1 0 0 1</diffuse>
            <specular>0.01 0.01 0.01 1</specular>
          </material>
        </visual>
        <self_collide>0</self_collide>
        <enable_wind>0</enable_wind>
        <kinematic>0</kinematic>
      </link>
      <link name='arm_wrist_lift'>
        <pose>1.6 0 1.05 0 -0 0</pose>
        <inertial>
          <pose>0 0 0 0 -0 0</pose>
          <inertia>
            <ixx>0.01</ixx>
            <ixy>0</ixy>
            <ixz>0</ixz>
            <iyy>0.01</iyy>
            <iyz>0</iyz>
            <izz>0.001</izz>
          </inertia>
          <mass>0.1</mass>
        </inertial>
        <collision name='arm_wrist_lift_geom'>
          <pose>0 0 0.5 0 -0 0</pose>
          <geometry>
            <cylinder>
              <radius>0.03</radius>
              <length>1</length>
            </cylinder>
          </geometry>
          <max_contacts>10</max_contacts>
          <surface>
            <contact>
              <ode/>
            </contact>
            <bounce/>
            <friction>
              <torsional>
                <ode/>
              </torsional>
              <ode/>
            </friction>
          </surface>
        </collision>
        <visual name='arm_wrist_lift_geom_visual'>
          <pose>0 0 0.5 0 -0 0</pose>
          <geometry>
            <cylinder>
              <radius>0.03</radius>
              <length>1</length>
            </cylinder>
          </geometry>
          <material>
            <ambient>1 1 0 1</ambient>
            <diffuse>1 1 0 1</diffuse>
            <specular>0.01 0.01 0.01 1</specular>
          </material>
        </visual>
        <self_collide>0</self_collide>
        <enable_wind>0</enable_wind>
        <kinematic>0</kinematic>
      </link>
      <link name='arm_wrist_roll'>
        <pose>1.6 0 1 0 -0 0</pose>
        <inertial>
          <pose>0 0 0 0 -0 0</pose>
          <inertia>
            <ixx>0.01</ixx>
            <ixy>0</ixy>
            <ixz>0</ixz>
            <iyy>0.01</iyy>
            <iyz>0</iyz>
            <izz>0.001</izz>
          </inertia>
          <mass>0.1</mass>
        </inertial>
        <collision name='arm_wrist_roll_geom'>
          <pose>0 0 0.025 0 -0 0</pose>
          <geometry>
            <cylinder>
              <radius>0.05</radius>
              <length>0.05</length>
            </cylinder>
          </geometry>
          <max_contacts>10</max_contacts>
          <surface>
            <contact>
              <ode/>
            </contact>
            <bounce/>
            <friction>
              <torsional>
                <ode/>
              </torsional>
              <ode/>
            </friction>
          </surface>
        </collision>
        <visual name='arm_wrist_roll_geom_visual'>
          <pose>0 0 0.025 0 -0 0</pose>
          <geometry>
            <cylinder>
              <radius>0.05</radius>
              <length>0.05</length>
            </cylinder>
          </geometry>
          <material>
            <ambient>1 0 0 1</ambient>
            <diffuse>1 0 0 1</diffuse>
            <specular>0.01 0.01 0.01 1</specular>
          </material>
        </visual>
        <self_collide>0</self_collide>
        <enable_wind>0</enable_wind>
        <kinematic>0</kinematic>
      </link>
      <joint name='arm_shoulder_pan_joint' type='revolute'>
        <parent>arm_base</parent>
        <child>arm_shoulder_pan</child>
        <axis>
          <dynamics>
            <damping>1</damping>
            <friction>0</friction>
            <spring_reference>0</spring_reference>
            <spring_stiffness>0</spring_stiffness>
          </dynamics>
          <xyz expressed_in='__model__'>0 0 1</xyz>
          <limit>
            <lower>-1e+16</lower>
            <upper>1e+16</upper>
          </limit>
        </axis>
      </joint>
      <joint name='arm_elbow_pan_joint' type='revolute'>
        <parent>arm_shoulder_pan</parent>
        <child>arm_elbow_pan</child>
        <axis>
          <dynamics>
            <damping>1</damping>
            <friction>0</friction>
            <spring_reference>0</spring_reference>
            <spring_stiffness>0</spring_stiffness>
          </dynamics>
          <xyz expressed_in='__model__'>0 0 1</xyz>
          <limit>
            <lower>-1e+16</lower>
            <upper>1e+16</upper>
          </limit>
        </axis>
      </joint>
      <joint name='arm_wrist_lift_joint' type='prismatic'>
        <parent>arm_elbow_pan</parent>
        <child>arm_wrist_lift</child>
        <axis>
          <dynamics>
            <damping>1</damping>
            <friction>0</friction>
            <spring_reference>0</spring_reference>
            <spring_stiffness>0</spring_stiffness>
          </dynamics>
          <limit>
            <lower>-0.8</lower>
            <upper>0.1</upper>
          </limit>
          <xyz expressed_in='__model__'>0 0 1</xyz>
        </axis>
      </joint>
      <joint name='arm_wrist_roll_joint' type='revolute'>
        <parent>arm_wrist_lift</parent>
        <child>arm_wrist_roll</child>
        <axis>
          <dynamics>
            <damping>1</damping>
            <friction>0</friction>
            <spring_reference>0</spring_reference>
            <spring_stiffness>0</spring_stiffness>
          </dynamics>
          <limit>
            <lower>-2.99999</lower>
            <upper>2.99999</upper>
          </limit>
          <xyz expressed_in='__model__'>0 0 1</xyz>
        </axis>
      </joint>
      <pose>1.10447 3.1994 0 0 -0 0</pose>
    </model>
    <model name='Construction Cone'>
      <link name='link'>
        <collision name='collision'>
          <geometry>
            <mesh>
              <scale>10 10 10</scale>
              <uri>model://construction_cone/meshes/construction_cone.dae</uri>
            </mesh>
          </geometry>
          <max_contacts>10</max_contacts>
          <surface>
            <contact>
              <ode/>
            </contact>
            <bounce/>
            <friction>
              <torsional>
                <ode/>
              </torsional>
              <ode/>
            </friction>
          </surface>
        </collision>
        <visual name='visual'>
          <geometry>
            <mesh>
              <scale>10 10 10</scale>
              <uri>model://construction_cone/meshes/construction_cone.dae</uri>
            </mesh>
          </geometry>
        </visual>
        <self_collide>0</self_collide>
        <inertial>
          <pose>0 0 0 0 -0 0</pose>
          <inertia>
            <ixx>1</ixx>
            <ixy>0</ixy>
            <ixz>0</ixz>
            <iyy>1</iyy>
            <iyz>0</iyz>
            <izz>1</izz>
          </inertia>
          <mass>1</mass>
        </inertial>
        <enable_wind>0</enable_wind>
        <kinematic>0</kinematic>
      </link>
      <pose>1.32434 -1.61393 0 0 -0 0</pose>
    </model>
    <model name='fire_hydrant'>
      <static>1</static>
      <link name='link'>
        <collision name='collision'>
          <geometry>
            <mesh>
              <uri>model://fire_hydrant/meshes/fire_hydrant.dae</uri>
            </mesh>
          </geometry>
          <max_contacts>10</max_contacts>
          <surface>
            <contact>
              <ode/>
            </contact>
            <bounce/>
            <friction>
              <torsional>
                <ode/>
              </torsional>
              <ode/>
            </friction>
          </surface>
        </collision>
        <visual name='visual'>
          <geometry>
            <mesh>
              <uri>model://fire_hydrant/meshes/fire_hydrant.dae</uri>
            </mesh>
          </geometry>
        </visual>
        <self_collide>0</self_collide>
        <enable_wind>0</enable_wind>
        <kinematic>0</kinematic>
      </link>
      <pose>-2.4535 3.34081 0 0 -0 0</pose>
    </model>
    <state world_name='default'>
      <sim_time>885 533000000</sim_time>
      <real_time>1060 151992565</real_time>
      <wall_time>1723252996 690852185</wall_time>
      <iterations>885533</iterations>
      <model name='Construction Cone'>
        <pose>2.71147 0.021327 -0 0 -1e-06 -0.004505</pose>
        <scale>1 1 1</scale>
        <link name='link'>
          <pose>2.71147 0.021327 -0 0 -1e-06 -0.004505</pose>
          <velocity>0 0 0 0 -0 0</velocity>
          <acceleration>-0 0 0.008512 2.57682 -1.13934 -3.14159</acceleration>
          <wrench>-0 0 0.008512 0 -0 0</wrench>
        </link>
      </model>
      <model name='fire_hydrant'>
        <pose>-2.4535 3.34081 0 0 -0 0</pose>
        <scale>1 1 1</scale>
        <link name='link'>
          <pose>-2.4535 3.34081 0 0 -0 0</pose>
          <velocity>0 0 0 0 -0 0</velocity>
          <acceleration>0 0 0 0 -0 0</acceleration>
          <wrench>0 0 0 0 -0 0</wrench>
        </link>
      </model>
      <model name='ground_plane'>
        <pose>0 0 0 0 -0 0</pose>
        <scale>1 1 1</scale>
        <link name='link'>
          <pose>0 0 0 0 -0 0</pose>
          <velocity>0 0 0 0 -0 0</velocity>
          <acceleration>0 0 0 0 -0 0</acceleration>
          <wrench>0 0 0 0 -0 0</wrench>
        </link>
      </model>
      <model name='plane'>
        <pose>-1.97088 -2.37934 0.124447 0 -0 0</pose>
        <scale>1 1 1</scale>
        <link name='base_link'>
          <pose>-1.97088 -2.37934 0.124447 0 -0 0</pose>
          <velocity>0 0 -0 0 -0 0</velocity>
          <acceleration>0 0 -0 0 -0 0</acceleration>
          <wrench>0 0 -0 0 -0 0</wrench>
        </link>
        <link name='elevator'>
          <pose>-1.97088 -2.37934 0.124447 0 -0 0</pose>
          <velocity>0 0 -0 0 -0 0</velocity>
          <acceleration>0 0 0 0 -0 0</acceleration>
          <wrench>0 0 0 0 -0 0</wrench>
        </link>
        <link name='left_elevon'>
          <pose>-1.97088 -2.37934 0.124447 0 5e-06 0</pose>
          <velocity>-0 0 -0 0 -0 0</velocity>
          <acceleration>0 0 -0 0 -0 0</acceleration>
          <wrench>0 0 -0 0 -0 0</wrench>
        </link>
        <link name='left_flap'>
          <pose>-1.97088 -2.37934 0.124447 0 5e-06 0</pose>
          <velocity>-0 0 -0 0 -0 0</velocity>
          <acceleration>0 0 -0 0 -0 0</acceleration>
          <wrench>0 0 -0 0 -0 0</wrench>
        </link>
        <link name='right_elevon'>
          <pose>-1.97088 -2.37934 0.124447 0 5e-06 0</pose>
          <velocity>-0 0 -0 0 -0 0</velocity>
          <acceleration>0 0 0 0 -0 0</acceleration>
          <wrench>0 0 0 0 -0 0</wrench>
        </link>
        <link name='right_flap'>
          <pose>-1.97088 -2.37934 0.124447 0 5e-06 0</pose>
          <velocity>-0 0 -0 0 -0 0</velocity>
          <acceleration>0 0 0 0 -0 0</acceleration>
          <wrench>0 0 0 0 -0 0</wrench>
        </link>
        <link name='rotor_puller'>
          <pose>-1.67088 -2.37934 0.124447 0 1.57 0</pose>
          <velocity>0 0 -0 0 -0 0</velocity>
          <acceleration>0 0 -0 0 -0 0</acceleration>
          <wrench>0 0 -0 0 -0 0</wrench>
        </link>
        <link name='rudder'>
          <pose>-1.97088 -2.37934 0.124447 0 -0 0</pose>
          <velocity>0 0 -0 0 -0 0</velocity>
          <acceleration>0 0 0 0 -0 0</acceleration>
          <wrench>0 0 0 0 -0 0</wrench>
        </link>
      </model>
      <model name='rover_ackermann'>
        <pose>0.022688 -1.87032 0.059943 -1e-05 0.000271 1.88317</pose>
        <scale>1 1 1</scale>
        <link name='base_link'>
          <pose>0.022688 -1.87032 0.059943 -1e-05 0.000271 1.88317</pose>
          <velocity>-0.000415 -0.016798 0.002529 0.003173 -0.054727 0.02808</velocity>
          <acceleration>0.185802 -0.229949 5.90388 2.83156 -1.20266 -2.54142</acceleration>
          <wrench>0.557407 -0.689848 17.7117 0 -0 0</wrench>
        </link>
        <link name='rover_ackermann/FrontLeftWheel'>
          <pose>-0.109338 -1.78686 0.059998 3.1415 0.853169 -1.78211</pose>
          <velocity>-0.000377 -0.020845 -0.002251 0.355762 -0.00332 -0.037199</velocity>
          <acceleration>5.3292 0.32873 -12.8624 0.969312 0.396396 1.58573</acceleration>
          <wrench>0.26646 0.016436 -0.643122 0 -0 0</wrench>
        </link>
        <link name='rover_ackermann/FrontLeftWheelSteering'>
          <pose>-0.109338 -1.78686 0.06002 0.00053 0.000239 1.35952</pose>
          <velocity>-0.000718 -0.021051 -0.002078 0.059328 0.209403 -0.045562</velocity>
          <acceleration>5.09144 0.031816 -12.1187 0.912915 0.894604 0.999084</acceleration>
          <wrench>0.025457 0.000159 -0.060594 0 -0 0</wrench>
        </link>
        <link name='rover_ackermann/FrontRightWheel'>
          <pose>0.08096 -1.72539 0.060001 3.14144 0.55827 -1.78223</pose>
          <velocity>-0.003717 -0.01533 0.010997 0.142645 -0.03708 0.020195</velocity>
          <acceleration>0.220882 -0.450783 38.3063 2.20063 -1.00224 -1.46945</acceleration>
          <wrench>0.011044 -0.022539 1.91532 0 -0 0</wrench>
        </link>
        <link name='rover_ackermann/FrontRightWheelSteering'>
          <pose>0.080959 -1.72539 0.060024 -7e-06 0.00023 1.35949</pose>
          <velocity>-0.00379 -0.015277 0.012228 0.021123 0.028675 0.023265</velocity>
          <acceleration>0.013985 -0.408886 44.1535 0.568475 -0.802154 2.40523</acceleration>
          <wrench>7e-05 -0.002044 0.220768 0 -0 0</wrench>
        </link>
        <link name='rover_ackermann/RearLeftWheel'>
          <pose>-0.013466 -2.08376 0.06 -8.8e-05 -1.18696 1.88327</pose>
          <velocity>0.004882 -0.017965 0.000111 0.275909 0.07143 0.025562</velocity>
          <acceleration>-2.11142 0.112453 3.25727 0.383792 -0.135845 -0.498022</acceleration>
          <wrench>-0.105571 0.005623 0.162863 0 -0 0</wrench>
        </link>
        <link name='rover_ackermann/RearRightWheel'>
          <pose>0.176852 -2.0223 0.06 3.14116 0.983777 -1.25887</pose>
          <velocity>0.00411 -0.012396 0.010849 -0.052751 -0.014663 0.012105</velocity>
          <acceleration>-1.23522 -1.62028 35.5635 -0.243651 0.729784 0.616718</acceleration>
          <wrench>-0.061761 -0.081014 1.77817 0 -0 0</wrench>
        </link>
      </model>
      <model name='simple_arm'>
        <pose>1.10447 3.1994 -6e-06 0 -1.1e-05 -7e-06</pose>
        <scale>1 1 1</scale>
        <link name='arm_base'>
          <pose>1.10447 3.1994 -6e-06 0 -1.1e-05 -7e-06</pose>
          <velocity>-0 0 -0.000439 -5e-06 -0.020897 0</velocity>
          <acceleration>-0.041904 8.7e-05 0.043279 3.13352 1.03048 -3.14159</acceleration>
          <wrench>-4.23226 0.00877 4.37122 0 -0 0</wrench>
        </link>
        <link name='arm_elbow_pan'>
          <pose>2.15446 3.19992 1.09999 -0 1.7e-05 -0.001024</pose>
          <velocity>-0.0229 -2.7e-05 0.011637 -9e-06 -0.002512 0.000106</velocity>
          <acceleration>-46.0059 -0.034672 22.8828 3.13117 -1.26449 -2.92673</acceleration>
          <wrench>-55.207 -0.041606 27.4593 0 -0 0</wrench>
        </link>
        <link name='arm_shoulder_pan'>
          <pose>1.10446 3.1994 1.09999 0 -2.1e-05 0.000495</pose>
          <velocity>-0.022999 6e-06 -0.001608 1e-06 -0.027348 -3.2e-05</velocity>
          <acceleration>-46.0832 0.006572 0.032131 -0.025481 0.623428 -0.062549</acceleration>
          <wrench>-50.6915 0.007229 0.035345 0 -0 0</wrench>
        </link>
        <link name='arm_wrist_lift'>
          <pose>2.70444 3.19935 0.249959 0 2.5e-05 -0.001024</pose>
          <velocity>-0.023005 2e-05 -0.012187 -1.4e-05 0.001518 7.6e-05</velocity>
          <acceleration>-48.5206 0.04412 -9.80649 -0.021325 1.35346 0.155118</acceleration>
          <wrench>-4.85206 0.004412 -0.980649 0 -0 0</wrench>
        </link>
        <link name='arm_wrist_roll'>
          <pose>2.70444 3.19935 0.199958 0 2.6e-05 -0.000227</pose>
          <velocity>-0.023943 1.9e-05 -0.011902 -1.6e-05 0.002723 -7.9e-05</velocity>
          <acceleration>-50.5844 0.041863 -9.87762 3.11554 -0.580926 2.98286</acceleration>
          <wrench>-5.05844 0.004186 -0.987762 0 -0 0</wrench>
        </link>
      </model>
      <model name='x500_base'>
        <pose>-6.75763 -0.846007 0.226502 -0.000262 0 0</pose>
        <scale>1 1 1</scale>
        <link name='base_link'>
          <pose>-6.75763 -0.846007 0.226502 -0.000262 0 0</pose>
          <velocity>0 0 0 0 1e-06 0</velocity>
          <acceleration>0.000486 0 0 0 0.002142 0</acceleration>
          <wrench>0.000973 0 0 0 -0 0</wrench>
        </link>
        <link name='rotor_0'>
          <pose>-6.58363 -1.01999 0.286548 -0.000262 0 0</pose>
          <velocity>0 0 -0 0 1e-06 0</velocity>
          <acceleration>0.000829 0.000116 -0.000405 -0 0.002332 -1e-06</acceleration>
          <wrench>1.3e-05 2e-06 -7e-06 0 -0 0</wrench>
        </link>
        <link name='rotor_1'>
          <pose>-6.93163 -0.671991 0.286456 -0.000262 0 0</pose>
          <velocity>0 0 0 0 1e-06 0</velocity>
          <acceleration>0.000597 -0.000112 0.000401 -9e-06 0.002315 -1e-06</acceleration>
          <wrench>1e-05 -2e-06 6e-06 0 -0 0</wrench>
        </link>
        <link name='rotor_2'>
          <pose>-6.58363 -0.671991 0.286456 -0.000262 0 0</pose>
          <velocity>0 0 -0 0 1e-06 0</velocity>
          <acceleration>0.000594 0.000115 -0.000402 -2e-05 0.002299 -1e-06</acceleration>
          <wrench>1e-05 2e-06 -6e-06 0 -0 0</wrench>
        </link>
        <link name='rotor_3'>
          <pose>-6.93163 -1.01999 0.286548 -0.000262 0 0</pose>
          <velocity>0 0 0 0 1e-06 0</velocity>
          <acceleration>0.000823 -0.000116 0.000398 -9e-06 0.002283 -1e-06</acceleration>
          <wrench>1.3e-05 -2e-06 6e-06 0 -0 0</wrench>
        </link>
      </model>
      <model name='zero_turn_mower'>
        <pose>-4.76768 0.241979 0.195745 0 -0.005005 -0.033127</pose>
        <scale>1 1 1</scale>
        <link name='alarm_visual_link'>
          <pose>-5.22068 0.256991 0.843484 -0.000225 -0.005 0.01182</pose>
          <velocity>-3.7e-05 -0.000301 9e-06 1e-06 6e-06 3.1e-05</velocity>
          <acceleration>-0.031155 -0.210401 -0.053504 -0.00299 -0.04069 -8e-06</acceleration>
          <wrench>-0.031155 -0.210401 -0.053504 0 -0 0</wrench>
        </link>
        <link name='base_link'>
          <pose>-4.76768 0.241979 0.195745 0 -0.005005 -0.033127</pose>
          <velocity>-4e-05 -0.000253 6e-06 -0 6e-06 9.6e-05</velocity>
          <acceleration>-0.003265 -0.165402 -0.03503 0.001598 -0.040789 0.09838</acceleration>
          <wrench>-0.718201 -36.3884 -7.70667 0 -0 0</wrench>
        </link>
        <link name='cutter_blades_link'>
          <pose>-4.56729 0.235338 0.096747 -0.000225 -0.005 0.01182</pose>
          <velocity>-4e-05 -0.000236 5e-06 1e-06 6e-06 3.1e-05</velocity>
          <acceleration>0.001374 -0.147925 -0.026853 -0.002998 -0.04069 -8e-06</acceleration>
          <wrench>0.001374 -0.147925 -0.026853 0 -0 0</wrench>
        </link>
        <link name='engine_visual_link'>
          <pose>-5.66967 0.27187 0.691234 -0.000467 -0.005005 -0.033127</pose>
          <velocity>-4e-05 -0.000345 1.2e-05 -2e-06 6e-06 9.8e-05</velocity>
          <acceleration>-0.026446 -0.255738 -0.071817 -0.001849 -0.040727 0.099677</acceleration>
          <wrench>-0.026446 -0.255738 -0.071817 0 -0 0</wrench>
        </link>
        <link name='left_wheel_link'>
          <pose>-5.20263 0.70664 0.214992 -1.57079 1.53123 -0.033113</pose>
          <velocity>-8.9e-05 -0.00013 1.4e-05 0.00057 -0.000462 0.000114</velocity>
          <acceleration>-0.054326 -0.091631 -0.053882 0.404692 -0.158588 0.224444</acceleration>
          <wrench>-0.434606 -0.733045 -0.431058 0 -0 0</wrench>
        </link>
        <link name='right_wheel_link'>
          <pose>-5.23244 -0.192866 0.214992 -1.57079 1.39769 -0.033121</pose>
          <velocity>1.4e-05 -0.000134 5e-06 0.000588 2.3e-05 8.7e-05</velocity>
          <acceleration>0.048496 -0.095261 -0.052721 0.413505 0.081474 0.179085</acceleration>
          <wrench>0.387965 -0.762087 -0.421767 0 -0 0</wrench>
        </link>
      </model>
      <light name='sun'>
        <pose>0 0 10 0 -0 0</pose>
      </light>
    </state>
    <gui fullscreen='0'>
      <camera name='user_camera'>
        <pose>7.91902 -6.12515 5.49423 0 0.589964 2.35603</pose>
        <view_controller>orbit</view_controller>
        <projection_type>perspective</projection_type>
      </camera>
    </gui>
  </world>
</sdf>
