<sdf version='1.7'>
  <world name='default'>
    <light name='sun' type='directional'>
      <cast_shadows>1</cast_shadows>
      <pose>0 0 10 0 -0 0</pose>
      <diffuse>0.8 0.8 0.8 1</diffuse>
      <specular>0.2 0.2 0.2 1</specular>
      <attenuation>
        <range>1000</range>
        <constant>0.9</constant>
        <linear>0.01</linear>
        <quadratic>0.001</quadratic>
      </attenuation>
      <direction>-0.5 0.1 -0.9</direction>
      <spot>
        <inner_angle>0</inner_angle>
        <outer_angle>0</outer_angle>
        <falloff>0</falloff>
      </spot>
    </light>
    <model name='ground_plane'>
      <static>1</static>
      <link name='link'>
        <collision name='collision'>
          <geometry>
            <plane>
              <normal>0 0 1</normal>
              <size>100 100</size>
            </plane>
          </geometry>
          <surface>
            <contact>
              <collide_bitmask>65535</collide_bitmask>
              <ode/>
            </contact>
            <friction>
              <ode>
                <mu>100</mu>
                <mu2>50</mu2>
              </ode>
              <torsional>
                <ode/>
              </torsional>
            </friction>
            <bounce/>
          </surface>
          <max_contacts>10</max_contacts>
        </collision>
        <visual name='visual'>
          <cast_shadows>0</cast_shadows>
          <geometry>
            <plane>
              <normal>0 0 1</normal>
              <size>100 100</size>
            </plane>
          </geometry>
          <material>
            <script>
              <uri>file://media/materials/scripts/gazebo.material</uri>
              <name>Gazebo/Grey</name>
            </script>
          </material>
        </visual>
        <self_collide>0</self_collide>
        <enable_wind>0</enable_wind>
        <kinematic>0</kinematic>
      </link>
    </model>
    <gravity>0 0 -9.8</gravity>
    <magnetic_field>6e-06 2.3e-05 -4.2e-05</magnetic_field>
    <atmosphere type='adiabatic'/>
    <physics type='ode'>
      <max_step_size>0.001</max_step_size>
      <real_time_factor>1</real_time_factor>
      <real_time_update_rate>1000</real_time_update_rate>
    </physics>
    <scene>
      <ambient>0.4 0.4 0.4 1</ambient>
      <background>0.7 0.7 0.7 1</background>
      <shadows>1</shadows>
    </scene>
    <audio>
      <device>default</device>
    </audio>
    <wind/>
    <spherical_coordinates>
      <surface_model>EARTH_WGS84</surface_model>
      <latitude_deg>0</latitude_deg>
      <longitude_deg>0</longitude_deg>
      <elevation>0</elevation>
      <heading_deg>0</heading_deg>
    </spherical_coordinates>
    <model name='robot'>
      <link name='base_link'>
        <inertial>
          <pose>0.117139 0 0.045333 0 -0 0</pose>
          <mass>0.9</mass>
          <inertia>
            <ixx>0.00183883</ixx>
            <ixy>0</ixy>
            <ixz>-1.64333e-05</ixz>
            <iyy>0.00273024</iyy>
            <iyz>0</iyz>
            <izz>0.00295493</izz>
          </inertia>
        </inertial>
        <collision name='base_link_fixed_joint_lump__chassis_link_collision'>
          <pose>0.0435 0 0.034 0 -0 0</pose>
          <geometry>
            <box>
              <size>0.247 0.2 0.068</size>
            </box>
          </geometry>
          <max_contacts>10</max_contacts>
          <surface>
            <contact>
              <ode/>
            </contact>
            <bounce/>
            <friction>
              <torsional>
                <ode/>
              </torsional>
              <ode/>
            </friction>
          </surface>
        </collision>
        <collision name='base_link_fixed_joint_lump__camera_link_collision_1'>
          <pose>0.167 0 0.034 0 -0 0</pose>
          <geometry>
            <box>
              <size>0.02 0.1 0.05</size>
            </box>
          </geometry>
          <surface>
            <contact>
              <ode/>
            </contact>
            <friction>
              <ode/>
              <torsional>
                <ode/>
              </torsional>
            </friction>
            <bounce/>
          </surface>
          <max_contacts>10</max_contacts>
        </collision>
        <collision name='base_link_fixed_joint_lump__caster_wheel_link_collision_2'>
          <pose>0.121875 0 0 0 -0 0</pose>
          <geometry>
            <sphere>
              <radius>0.03375</radius>
            </sphere>
          </geometry>
          <surface>
            <contact>
              <ode/>
            </contact>
            <friction>
              <ode>
                <mu>0.05</mu>
                <mu2>0.05</mu2>
              </ode>
              <torsional>
                <ode/>
              </torsional>
            </friction>
            <bounce/>
          </surface>
          <max_contacts>10</max_contacts>
        </collision>
        <collision name='base_link_fixed_joint_lump__lidar_link_collision_3'>
          <pose>0.12 0 0.068 0 -0 0</pose>
          <geometry>
            <cylinder>
              <length>0.025</length>
              <radius>0.03375</radius>
            </cylinder>
          </geometry>
          <surface>
            <contact>
              <ode/>
            </contact>
            <friction>
              <ode/>
              <torsional>
                <ode/>
              </torsional>
            </friction>
            <bounce/>
          </surface>
          <max_contacts>10</max_contacts>
        </collision>
        <visual name='base_link_fixed_joint_lump__chassis_link_visual'>
          <pose>0.0435 0 0.034 0 -0 0</pose>
          <geometry>
            <box>
              <size>0.247 0.2 0.068</size>
            </box>
          </geometry>
        </visual>
        <visual name='base_link_fixed_joint_lump__camera_link_visual_1'>
          <pose>0.172 0 0.034 0 -0 0</pose>
          <geometry>
            <box>
              <size>0.005 0.1 0.02</size>
            </box>
          </geometry>
          <material>
            <script>
              <name>Gazebo/Red</name>
              <uri>file://media/materials/scripts/gazebo.material</uri>
            </script>
          </material>
        </visual>
        <visual name='base_link_fixed_joint_lump__caster_wheel_link_visual_2'>
          <pose>0.121875 0 0 0 -0 0</pose>
          <geometry>
            <sphere>
              <radius>0.03375</radius>
            </sphere>
          </geometry>
          <material>
            <script>
              <name>Gazebo/Black</name>
              <uri>file://media/materials/scripts/gazebo.material</uri>
            </script>
          </material>
        </visual>
        <visual name='base_link_fixed_joint_lump__lidar_link_visual_3'>
          <pose>0.12 0 0.0805 0 -0 0</pose>
          <geometry>
            <cylinder>
              <length>0.025</length>
              <radius>0.02</radius>
            </cylinder>
          </geometry>
          <material>
            <script>
              <name>Gazebo/Red</name>
              <uri>file://media/materials/scripts/gazebo.material</uri>
            </script>
          </material>
        </visual>
        <sensor name='camera' type='camera'>
          <visualize>1</visualize>
          <update_rate>10</update_rate>
          <camera>
            <horizontal_fov>1.089</horizontal_fov>
            <image>
              <format>R8G8B8</format>
              <width>640</width>
              <height>480</height>
            </image>
            <clip>
              <near>0.05</near>
              <far>8</far>
            </clip>
          </camera>
          <plugin name='camera_controller' filename='libgazebo_ros_camera.so'>
            <frame_name>camera_link_optical</frame_name>
          </plugin>
          <pose>0.167 0 0.034 0 -0 0</pose>
        </sensor>
        <sensor name='laser' type='ray'>
          <visualize>1</visualize>
          <update_rate>10</update_rate>
          <ray>
            <scan>
              <horizontal>
                <samples>360</samples>
                <min_angle>-3.14</min_angle>
                <max_angle>3.14</max_angle>
                <resolution>1</resolution>
              </horizontal>
              <vertical>
                <samples>1</samples>
                <min_angle>0</min_angle>
                <max_angle>0</max_angle>
              </vertical>
            </scan>
            <range>
              <min>0.3</min>
              <max>12</max>
            </range>
          </ray>
          <plugin name='laser_controller' filename='libgazebo_ros_ray_sensor.so'>
            <ros>
              <argument>~/out:=scan</argument>
            </ros>
            <output_type>sensor_msgs/LaserScan</output_type>
            <frame_name>lidar_link</frame_name>
          </plugin>
          <pose>0.12 0 0.068 0 -0 0</pose>
        </sensor>
        <self_collide>0</self_collide>
        <enable_wind>0</enable_wind>
        <kinematic>0</kinematic>
      </link>
      <joint name='left_wheel_joint' type='revolute'>
        <pose relative_to='base_link'>0 0.1125 0 -1.5708 0 0</pose>
        <parent>base_link</parent>
        <child>left_wheel_link</child>
        <axis>
          <xyz>0 0 1</xyz>
          <limit>
            <lower>-1e+16</lower>
            <upper>1e+16</upper>
          </limit>
          <dynamics>
            <spring_reference>0</spring_reference>
            <spring_stiffness>0</spring_stiffness>
          </dynamics>
        </axis>
      </joint>
      <link name='left_wheel_link'>
        <pose relative_to='left_wheel_joint'>0 0 0 0 -0 0</pose>
        <inertial>
          <pose>0 0 0 0 -0 0</pose>
          <mass>0.5</mass>
          <inertia>
            <ixx>0.000595573</ixx>
            <ixy>0</ixy>
            <ixz>0</ixz>
            <iyy>0.000595573</iyy>
            <iyz>0</iyz>
            <izz>0.00113906</izz>
          </inertia>
        </inertial>
        <collision name='left_wheel_link_collision'>
          <pose>0 0 0 0 -0 0</pose>
          <geometry>
            <cylinder>
              <length>0.025</length>
              <radius>0.03375</radius>
            </cylinder>
          </geometry>
          <surface>
            <contact>
              <ode/>
            </contact>
            <friction>
              <ode/>
              <torsional>
                <ode/>
              </torsional>
            </friction>
            <bounce/>
          </surface>
          <max_contacts>10</max_contacts>
        </collision>
        <visual name='left_wheel_link_visual'>
          <pose>0 0 0 0 -0 0</pose>
          <geometry>
            <cylinder>
              <length>0.025</length>
              <radius>0.03375</radius>
            </cylinder>
          </geometry>
          <material>
            <script>
              <name>Gazebo/Blue</name>
              <uri>file://media/materials/scripts/gazebo.material</uri>
            </script>
          </material>
        </visual>
        <self_collide>0</self_collide>
        <enable_wind>0</enable_wind>
        <kinematic>0</kinematic>
      </link>
      <joint name='right_wheel_joint' type='revolute'>
        <pose relative_to='base_link'>0 -0.1125 0 1.5708 -0 0</pose>
        <parent>base_link</parent>
        <child>right_wheel_link</child>
        <axis>
          <xyz>0 0 -1</xyz>
          <limit>
            <lower>-1e+16</lower>
            <upper>1e+16</upper>
          </limit>
          <dynamics>
            <spring_reference>0</spring_reference>
            <spring_stiffness>0</spring_stiffness>
          </dynamics>
        </axis>
      </joint>
      <link name='right_wheel_link'>
        <pose relative_to='right_wheel_joint'>0 0 0 0 -0 0</pose>
        <inertial>
          <pose>0 0 0 0 -0 0</pose>
          <mass>0.5</mass>
          <inertia>
            <ixx>0.000595573</ixx>
            <ixy>0</ixy>
            <ixz>0</ixz>
            <iyy>0.000595573</iyy>
            <iyz>0</iyz>
            <izz>0.00113906</izz>
          </inertia>
        </inertial>
        <collision name='right_wheel_link_collision'>
          <pose>0 0 0 0 -0 0</pose>
          <geometry>
            <cylinder>
              <length>0.025</length>
              <radius>0.03375</radius>
            </cylinder>
          </geometry>
          <surface>
            <contact>
              <ode/>
            </contact>
            <friction>
              <ode/>
              <torsional>
                <ode/>
              </torsional>
            </friction>
            <bounce/>
          </surface>
          <max_contacts>10</max_contacts>
        </collision>
        <visual name='right_wheel_link_visual'>
          <pose>0 0 0 0 -0 0</pose>
          <geometry>
            <cylinder>
              <length>0.025</length>
              <radius>0.03375</radius>
            </cylinder>
          </geometry>
          <material>
            <script>
              <name>Gazebo/Blue</name>
              <uri>file://media/materials/scripts/gazebo.material</uri>
            </script>
          </material>
        </visual>
        <self_collide>0</self_collide>
        <enable_wind>0</enable_wind>
        <kinematic>0</kinematic>
      </link>
      <static>0</static>
      <plugin name='diff_drive' filename='libgazebo_ros_diff_drive.so'>
        <left_joint>left_wheel_joint</left_joint>
        <right_joint>right_wheel_joint</right_joint>
        <wheel_separation>0.35</wheel_separation>
        <wheel_diameter>0.1</wheel_diameter>
        <max_wheel_torque>200</max_wheel_torque>
        <max_wheel_acceleration>10.0</max_wheel_acceleration>
        <odometry_frame>odom</odometry_frame>
        <robot_base_frame>base_link</robot_base_frame>
        <publish_odom>1</publish_odom>
        <publish_odom_tf>1</publish_odom_tf>
        <publish_wheel_tf>1</publish_wheel_tf>
      </plugin>
      <pose>0 0 0 0 -0 0</pose>
    </model>
    <model name='Sofa'>
      <link name='link'>
        <pose>0 0 0 0 -0 1.5708</pose>
        <visual name='visual'>
          <geometry>
            <mesh>
              <uri>https://fuel.ignitionrobotics.org/1.0/sebbyjp/models/sofa/1/files/meshes/Sofa.obj</uri>
            </mesh>
          </geometry>
        </visual>
        <collision name='collision'>
          <geometry>
            <mesh>
              <uri>https://fuel.ignitionrobotics.org/1.0/sebbyjp/models/sofa/1/files/meshes/Sofa.obj</uri>
            </mesh>
          </geometry>
          <max_contacts>10</max_contacts>
          <surface>
            <contact>
              <ode/>
            </contact>
            <bounce/>
            <friction>
              <torsional>
                <ode/>
              </torsional>
              <ode/>
            </friction>
          </surface>
        </collision>
        <self_collide>0</self_collide>
        <inertial>
          <pose>0 0 0 0 -0 0</pose>
          <inertia>
            <ixx>1</ixx>
            <ixy>0</ixy>
            <ixz>0</ixz>
            <iyy>1</iyy>
            <iyz>0</iyz>
            <izz>1</izz>
          </inertia>
          <mass>1</mass>
        </inertial>
        <enable_wind>0</enable_wind>
        <kinematic>0</kinematic>
      </link>
      <pose>4.85009 3.88316 0 0 -0 0</pose>
    </model>
    <model name='Electrical_Array_8'>
      <static>1</static>
      <link name='link'>
        <collision name='collision'>
          <geometry>
            <mesh>
              <uri>https://fuel.ignitionrobotics.org/1.0/kevinhalim9/models/electrical array 8/1/files/Meshes/Electrical_Array_8.stl</uri>
              <scale>0.001 0.001 0.001</scale>
            </mesh>
          </geometry>
          <max_contacts>10</max_contacts>
          <surface>
            <contact>
              <ode/>
            </contact>
            <bounce/>
            <friction>
              <torsional>
                <ode/>
              </torsional>
              <ode/>
            </friction>
          </surface>
        </collision>
        <visual name='visual'>
          <geometry>
            <mesh>
              <uri>https://fuel.ignitionrobotics.org/1.0/kevinhalim9/models/electrical array 8/1/files/Meshes/Electrical_Array_8.stl</uri>
              <scale>0.001 0.001 0.001</scale>
            </mesh>
          </geometry>
          <material>
            <diffuse>0.39 0 1 1</diffuse>
          </material>
        </visual>
        <self_collide>0</self_collide>
        <enable_wind>0</enable_wind>
        <kinematic>0</kinematic>
      </link>
      <pose>2.95506 1.35848 0 0 -0 0</pose>
    </model>
    <model name='zero_turn_mower'>
      <pose>5.11375 -1.31637 0.246 0 -0 0</pose>
      <link name='base_link'>
        <pose>0 0 0 0 -0 0</pose>
        <inertial>
          <pose>0 0 0 0 -0 0</pose>
          <mass>220</mass>
          <inertia>
            <ixx>40</ixx>
            <ixy>0</ixy>
            <iyy>150</iyy>
            <ixz>0</ixz>
            <iyz>0</iyz>
            <izz>150</izz>
          </inertia>
        </inertial>
        <collision name='base_collision'>
          <pose>0 0 0.2 0 -0 0</pose>
          <geometry>
            <box>
              <size>1.8 0.65 0.55</size>
            </box>
          </geometry>
          <surface>
            <contact>
              <ode/>
            </contact>
            <friction>
              <ode/>
              <torsional>
                <ode/>
              </torsional>
            </friction>
            <bounce/>
          </surface>
          <max_contacts>10</max_contacts>
        </collision>
        <visual name='base_visual_base'>
          <pose>0 0 0 0 -0 0</pose>
          <geometry>
            <box>
              <size>1.81 0.66 0.1</size>
            </box>
          </geometry>
          <material>
            <ambient>0.9 0.36 0 1</ambient>
            <diffuse>0.9 0.36 0 1</diffuse>
            <specular>0 0 0 0</specular>
            <emissive>0 0 0 1</emissive>
          </material>
        </visual>
        <visual name='base_visual'>
          <pose>-0.5 0 0.2 0 -0 0</pose>
          <geometry>
            <box>
              <size>0.8 0.65 0.55</size>
            </box>
          </geometry>
          <material>
            <ambient>1 0.4 0 1</ambient>
            <diffuse>1 0.4 0 1</diffuse>
            <specular>0 0 0 0</specular>
            <emissive>0.2 0.08 0 1</emissive>
          </material>
        </visual>
        <visual name='base_visual_cutter_r'>
          <pose>0.2 -0.5 -0.1 0 -0 0</pose>
          <geometry>
            <cylinder>
              <radius>0.25</radius>
              <length>0.1</length>
            </cylinder>
          </geometry>
          <material>
            <ambient>1 0.4 0 1</ambient>
            <diffuse>1 0.4 0 1</diffuse>
            <specular>0 0 0 0</specular>
            <emissive>0.2 0.08 0 1</emissive>
          </material>
        </visual>
        <visual name='base_visual_cutter_c'>
          <pose>0.23 0 -0.1 0 -0 0</pose>
          <geometry>
            <cylinder>
              <radius>0.25</radius>
              <length>0.1</length>
            </cylinder>
          </geometry>
          <material>
            <ambient>1 0.4 0 1</ambient>
            <diffuse>1 0.4 0 1</diffuse>
            <specular>0 0 0 0</specular>
            <emissive>0.2 0.08 0 1</emissive>
          </material>
        </visual>
        <visual name='base_visual_cutter_l'>
          <pose>0.2 0.5 -0.1 0 -0 0</pose>
          <geometry>
            <cylinder>
              <radius>0.25</radius>
              <length>0.1</length>
            </cylinder>
          </geometry>
          <material>
            <ambient>1 0.4 0 1</ambient>
            <diffuse>1 0.4 0 1</diffuse>
            <specular>0 0 0 0</specular>
            <emissive>0.2 0.08 0 1</emissive>
          </material>
        </visual>
        <collision name='left_caster_collision'>
          <pose>0.85 0.38 -0.1 0 -0 0</pose>
          <geometry>
            <sphere>
              <radius>0.1</radius>
            </sphere>
          </geometry>
          <surface>
            <friction>
              <ode>
                <mu>0</mu>
                <mu2>0</mu2>
                <slip1>1</slip1>
                <slip2>1</slip2>
              </ode>
              <torsional>
                <ode/>
              </torsional>
            </friction>
            <contact>
              <ode/>
            </contact>
            <bounce/>
          </surface>
          <max_contacts>10</max_contacts>
        </collision>
        <visual name='left_caster_visual_base'>
          <pose>0.85 0.38 -0.01 0 -0 0</pose>
          <geometry>
            <cylinder>
              <radius>0.1</radius>
              <length>0.1</length>
            </cylinder>
          </geometry>
          <material>
            <ambient>0.9 0.36 0 1</ambient>
            <diffuse>0.9 0.36 0 1</diffuse>
            <specular>0 0 0 0</specular>
            <emissive>0 0 0 1</emissive>
          </material>
        </visual>
        <visual name='left_caster_visual'>
          <pose>0.85 0.38 -0.1 0 -0 0</pose>
          <geometry>
            <sphere>
              <radius>0.1</radius>
            </sphere>
          </geometry>
          <material>
            <ambient>1 0.2 0.2 1</ambient>
            <diffuse>1 0.1 0.1 1</diffuse>
            <specular>0 0 0 0</specular>
            <emissive>0 0 0 1</emissive>
          </material>
        </visual>
        <collision name='right_caster_collision'>
          <pose>0.85 -0.38 -0.1 0 -0 0</pose>
          <geometry>
            <sphere>
              <radius>0.1</radius>
            </sphere>
          </geometry>
          <surface>
            <friction>
              <ode>
                <mu>0</mu>
                <mu2>0</mu2>
                <slip1>1</slip1>
                <slip2>1</slip2>
              </ode>
              <torsional>
                <ode/>
              </torsional>
            </friction>
            <contact>
              <ode/>
            </contact>
            <bounce/>
          </surface>
          <max_contacts>10</max_contacts>
        </collision>
        <visual name='right_caster_visual_base'>
          <pose>0.85 -0.38 -0.01 0 -0 0</pose>
          <geometry>
            <cylinder>
              <radius>0.1</radius>
              <length>0.1</length>
            </cylinder>
          </geometry>
          <material>
            <ambient>0.9 0.36 0 1</ambient>
            <diffuse>0.9 0.36 0 1</diffuse>
            <specular>0 0 0 0</specular>
            <emissive>0 0 0 1</emissive>
          </material>
        </visual>
        <visual name='right_caster_visual'>
          <pose>0.85 -0.38 -0.1 0 -0 0</pose>
          <geometry>
            <sphere>
              <radius>0.1</radius>
            </sphere>
          </geometry>
          <material>
            <ambient>0.2 1 0.2 1</ambient>
            <diffuse>0.1 1 0.1 1</diffuse>
            <specular>0 0 0 0</specular>
            <emissive>0 0 0 1</emissive>
          </material>
        </visual>
        <sensor name='air_pressure_sensor' type='air_pressure'>
          <always_on>1</always_on>
          <update_rate>50</update_rate>
          <air_pressure>
            <pressure>
              <noise type='gaussian'>
                <mean>0</mean>
                <stddev>0.01</stddev>
              </noise>
            </pressure>
          </air_pressure>
        </sensor>
        <sensor name='navsat_sensor' type='navsat'>
          <always_on>1</always_on>
          <update_rate>30</update_rate>
          <gps/>
        </sensor>
        <sensor name='imu_sensor' type='imu'>
          <always_on>1</always_on>
          <update_rate>250</update_rate>
          <imu>
            <angular_velocity>
              <x>
                <noise type='gaussian'>
                  <mean>0</mean>
                  <stddev>0.0003394</stddev>
                  <dynamic_bias_stddev>3.8785e-05</dynamic_bias_stddev>
                  <dynamic_bias_correlation_time>1000</dynamic_bias_correlation_time>
                </noise>
              </x>
              <y>
                <noise type='gaussian'>
                  <mean>0</mean>
                  <stddev>0.0003394</stddev>
                  <dynamic_bias_stddev>3.8785e-05</dynamic_bias_stddev>
                  <dynamic_bias_correlation_time>1000</dynamic_bias_correlation_time>
                </noise>
              </y>
              <z>
                <noise type='gaussian'>
                  <mean>0</mean>
                  <stddev>0.0003394</stddev>
                  <dynamic_bias_stddev>3.8785e-05</dynamic_bias_stddev>
                  <dynamic_bias_correlation_time>1000</dynamic_bias_correlation_time>
                </noise>
              </z>
            </angular_velocity>
            <linear_acceleration>
              <x>
                <noise type='gaussian'>
                  <mean>0</mean>
                  <stddev>0.004</stddev>
                  <dynamic_bias_stddev>0.006</dynamic_bias_stddev>
                  <dynamic_bias_correlation_time>300</dynamic_bias_correlation_time>
                </noise>
              </x>
              <y>
                <noise type='gaussian'>
                  <mean>0</mean>
                  <stddev>0.004</stddev>
                  <dynamic_bias_stddev>0.006</dynamic_bias_stddev>
                  <dynamic_bias_correlation_time>300</dynamic_bias_correlation_time>
                </noise>
              </y>
              <z>
                <noise type='gaussian'>
                  <mean>0</mean>
                  <stddev>0.004</stddev>
                  <dynamic_bias_stddev>0.006</dynamic_bias_stddev>
                  <dynamic_bias_correlation_time>300</dynamic_bias_correlation_time>
                </noise>
              </z>
            </linear_acceleration>
          </imu>
        </sensor>
        <self_collide>0</self_collide>
        <enable_wind>0</enable_wind>
        <kinematic>0</kinematic>
      </link>
      <link name='left_wheel_link'>
        <pose>-0.45 0.45 0.0215 1.57079 1.57079 3.14159</pose>
        <inertial>
          <mass>8</mass>
          <inertia>
            <ixx>0.5</ixx>
            <ixy>0</ixy>
            <iyy>0.5</iyy>
            <ixz>0</ixz>
            <iyz>0</iyz>
            <izz>1</izz>
          </inertia>
          <pose>0 0 0 0 -0 0</pose>
        </inertial>
        <collision name='left_wheel_link_collision'>
          <geometry>
            <cylinder>
              <radius>0.22</radius>
              <length>0.22</length>
            </cylinder>
          </geometry>
          <max_contacts>1</max_contacts>
          <surface>
            <friction>
              <ode>
                <mu>0.4</mu>
                <mu2>0.6</mu2>
              </ode>
              <torsional>
                <ode/>
              </torsional>
            </friction>
            <bounce/>
            <contact>
              <ode>
                <min_depth>0.005</min_depth>
                <kp>1e+08</kp>
              </ode>
            </contact>
          </surface>
        </collision>
        <visual name='left_wheel_link_visual'>
          <pose>0 0 0 1.5708 -0 0</pose>
          <geometry>
            <mesh>
              <scale>2.8 2 2.8</scale>
              <uri>https://fuel.ignitionrobotics.org/1.0/px4/models/lawnmower/1/files/meshes/wheel_link.STL</uri>
            </mesh>
          </geometry>
          <material>
            <script>
              <name>Gazebo/FlatBlack</name>
              <uri>file://media/materials/scripts/gazebo.material</uri>
            </script>
          </material>
        </visual>
        <visual name='left_wheel_marker_visual'>
          <pose>0.17 0 0 0 -0 0</pose>
          <geometry>
            <box>
              <size>0.1 0.01 0.21</size>
            </box>
          </geometry>
          <material>
            <ambient>1 0.2 0.2 1</ambient>
            <diffuse>1 0.1 0.1 1</diffuse>
            <specular>0 0 0 0</specular>
            <emissive>0 0 0 1</emissive>
          </material>
        </visual>
        <self_collide>0</self_collide>
        <enable_wind>0</enable_wind>
        <kinematic>0</kinematic>
      </link>
      <joint name='left_wheel_joint' type='revolute'>
        <child>left_wheel_link</child>
        <parent>base_link</parent>
        <axis>
          <xyz>0 0 1</xyz>
          <limit>
            <lower>-1e+16</lower>
            <upper>1e+16</upper>
          </limit>
          <dynamics>
            <spring_reference>0</spring_reference>
            <spring_stiffness>0</spring_stiffness>
          </dynamics>
        </axis>
      </joint>
      <link name='right_wheel_link'>
        <pose>-0.45 -0.45 0.0215 1.57079 1.57079 3.14159</pose>
        <inertial>
          <mass>8</mass>
          <inertia>
            <ixx>0.5</ixx>
            <ixy>0</ixy>
            <iyy>0.5</iyy>
            <ixz>0</ixz>
            <iyz>0</iyz>
            <izz>1</izz>
          </inertia>
          <pose>0 0 0 0 -0 0</pose>
        </inertial>
        <collision name='right_wheel_link_collision'>
          <geometry>
            <cylinder>
              <radius>0.22</radius>
              <length>0.22</length>
            </cylinder>
          </geometry>
          <max_contacts>1</max_contacts>
          <surface>
            <friction>
              <ode>
                <mu>0.4</mu>
                <mu2>0.6</mu2>
              </ode>
              <torsional>
                <ode/>
              </torsional>
            </friction>
            <bounce/>
            <contact>
              <ode>
                <min_depth>0.005</min_depth>
                <kp>1e+08</kp>
              </ode>
            </contact>
          </surface>
        </collision>
        <visual name='right_wheel_link_visual'>
          <pose>0 0 0 1.5708 -0 0</pose>
          <geometry>
            <mesh>
              <scale>2.8 2 2.8</scale>
              <uri>https://fuel.ignitionrobotics.org/1.0/px4/models/lawnmower/1/files/meshes/wheel_link.STL</uri>
            </mesh>
          </geometry>
          <material>
            <script>
              <name>Gazebo/FlatBlack</name>
              <uri>file://media/materials/scripts/gazebo.material</uri>
            </script>
          </material>
        </visual>
        <visual name='right_wheel_marker_visual'>
          <pose>0.17 0 0 0 -0 0</pose>
          <geometry>
            <box>
              <size>0.1 0.01 0.21</size>
            </box>
          </geometry>
          <material>
            <ambient>0.2 1 0.2 1</ambient>
            <diffuse>0.1 1 0.1 1</diffuse>
            <specular>0 0 0 0</specular>
            <emissive>0 0 0 1</emissive>
          </material>
        </visual>
        <self_collide>0</self_collide>
        <enable_wind>0</enable_wind>
        <kinematic>0</kinematic>
      </link>
      <joint name='right_wheel_joint' type='revolute'>
        <child>right_wheel_link</child>
        <parent>base_link</parent>
        <axis>
          <xyz>0 0 1</xyz>
          <limit>
            <lower>-1e+16</lower>
            <upper>1e+16</upper>
          </limit>
          <dynamics>
            <spring_reference>0</spring_reference>
            <spring_stiffness>0</spring_stiffness>
          </dynamics>
        </axis>
      </joint>
      <link name='engine_visual_link'>
        <pose>-0.9 0 0.5 0 -0 0</pose>
        <visual name='engine_visual_link_visual'>
          <pose>0 0 0 1.5708 -0 0</pose>
          <geometry>
            <cylinder>
              <radius>0.1</radius>
              <length>0.08</length>
            </cylinder>
          </geometry>
          <material>
            <ambient>0.3 0.3 0.2 1</ambient>
            <diffuse>1 1 0.1 1</diffuse>
            <specular>0 0 0 0</specular>
            <emissive>0 0 0 1</emissive>
          </material>
        </visual>
        <self_collide>0</self_collide>
        <inertial>
          <pose>0 0 0 0 -0 0</pose>
          <inertia>
            <ixx>1</ixx>
            <ixy>0</ixy>
            <ixz>0</ixz>
            <iyy>1</iyy>
            <iyz>0</iyz>
            <izz>1</izz>
          </inertia>
          <mass>1</mass>
        </inertial>
        <enable_wind>0</enable_wind>
        <kinematic>0</kinematic>
      </link>
      <joint name='engine_visual_joint' type='revolute'>
        <child>engine_visual_link</child>
        <parent>base_link</parent>
        <axis>
          <xyz>1 0 0</xyz>
          <limit>
            <lower>-1e+16</lower>
            <upper>1e+16</upper>
          </limit>
          <dynamics>
            <spring_reference>0</spring_reference>
            <spring_stiffness>0</spring_stiffness>
          </dynamics>
        </axis>
      </joint>
      <link name='cutter_blades_link'>
        <pose>0.2 0 -0.1 0 -0 0</pose>
        <visual name='cutter_blades_marker_visual'>
          <pose>0.8 0 0 0 -0 0</pose>
          <geometry>
            <box>
              <size>0.2 0.01 0.15</size>
            </box>
          </geometry>
          <material>
            <ambient>1 0 0 1</ambient>
            <diffuse>1 0 0 1</diffuse>
            <specular>0 0 0 0</specular>
            <emissive>0 0 0 1</emissive>
          </material>
        </visual>
        <self_collide>0</self_collide>
        <inertial>
          <pose>0 0 0 0 -0 0</pose>
          <inertia>
            <ixx>1</ixx>
            <ixy>0</ixy>
            <ixz>0</ixz>
            <iyy>1</iyy>
            <iyz>0</iyz>
            <izz>1</izz>
          </inertia>
          <mass>1</mass>
        </inertial>
        <enable_wind>0</enable_wind>
        <kinematic>0</kinematic>
      </link>
      <joint name='cutter_blades_joint' type='revolute'>
        <child>cutter_blades_link</child>
        <parent>base_link</parent>
        <axis>
          <xyz>0 0 1</xyz>
          <limit>
            <lower>-1e+16</lower>
            <upper>1e+16</upper>
          </limit>
          <dynamics>
            <spring_reference>0</spring_reference>
            <spring_stiffness>0</spring_stiffness>
          </dynamics>
        </axis>
      </joint>
      <link name='alarm_visual_link'>
        <pose>-0.45 0 0.65 0 -0 0</pose>
        <visual name='alarm_visual_sphere_visual'>
          <pose>0 0 0 1.5708 -0 0</pose>
          <geometry>
            <sphere>
              <radius>0.07</radius>
            </sphere>
          </geometry>
          <material>
            <ambient>0.7 0.7 0 1</ambient>
            <diffuse>0.7 0.7 0 1</diffuse>
            <specular>0 0 0 0</specular>
            <emissive>0 0 0 1</emissive>
          </material>
        </visual>
        <visual name='alarm_visual_belt_visual'>
          <pose>0 0 0 1.5708 -0 0</pose>
          <geometry>
            <cylinder>
              <radius>0.08</radius>
              <length>0.02</length>
            </cylinder>
          </geometry>
          <material>
            <ambient>1 0 0 1</ambient>
            <diffuse>1 0 0 1</diffuse>
            <specular>0 0 0 0</specular>
            <emissive>0 0 0 1</emissive>
          </material>
        </visual>
        <visual name='alarm_visual_support_visual'>
          <pose>0 0 -0.1 0 -0 0</pose>
          <geometry>
            <box>
              <size>0.05 0.05 0.2</size>
            </box>
          </geometry>
          <material>
            <ambient>0.7 0.7 0 1</ambient>
            <diffuse>0.7 0.7 0 1</diffuse>
            <specular>0 0 0 0</specular>
            <emissive>0 0 0 1</emissive>
          </material>
        </visual>
        <self_collide>0</self_collide>
        <inertial>
          <pose>0 0 0 0 -0 0</pose>
          <inertia>
            <ixx>1</ixx>
            <ixy>0</ixy>
            <ixz>0</ixz>
            <iyy>1</iyy>
            <iyz>0</iyz>
            <izz>1</izz>
          </inertia>
          <mass>1</mass>
        </inertial>
        <enable_wind>0</enable_wind>
        <kinematic>0</kinematic>
      </link>
      <joint name='alarm_visual_joint' type='revolute'>
        <child>alarm_visual_link</child>
        <parent>base_link</parent>
        <axis>
          <xyz>0 0 1</xyz>
          <limit>
            <lower>-1e+16</lower>
            <upper>1e+16</upper>
          </limit>
          <dynamics>
            <spring_reference>0</spring_reference>
            <spring_stiffness>0</spring_stiffness>
          </dynamics>
        </axis>
      </joint>
      <plugin name='gz::sim::systems::JointController' filename='gz-sim-joint-controller-system'>
        <joint_name>right_wheel_joint</joint_name>
        <sub_topic>command/motor_speed</sub_topic>
        <use_actuator_msg>1</use_actuator_msg>
        <actuator_number>0</actuator_number>
        <initial_velocity>0</initial_velocity>
        <use_force_commands>1</use_force_commands>
        <p_gain>5.0</p_gain>
        <i_gain>2.0</i_gain>
        <d_gain>0</d_gain>
        <i_max>1.0</i_max>
        <i_min>-1.0</i_min>
        <cmd_max>1000.0</cmd_max>
        <cmd_min>-1000.0</cmd_min>
        <cmd_offset>0.0</cmd_offset>
      </plugin>
      <plugin name='gz::sim::systems::JointController' filename='gz-sim-joint-controller-system'>
        <joint_name>left_wheel_joint</joint_name>
        <sub_topic>command/motor_speed</sub_topic>
        <use_actuator_msg>1</use_actuator_msg>
        <actuator_number>1</actuator_number>
        <initial_velocity>0</initial_velocity>
        <use_force_commands>1</use_force_commands>
        <p_gain>5.0</p_gain>
        <i_gain>2.0</i_gain>
        <d_gain>0</d_gain>
        <i_max>1.0</i_max>
        <i_min>-1.0</i_min>
        <cmd_max>1000.0</cmd_max>
        <cmd_min>-1000.0</cmd_min>
        <cmd_offset>0.0</cmd_offset>
      </plugin>
      <plugin name='gz::sim::systems::JointController' filename='gz-sim-joint-controller-system'>
        <joint_name>cutter_blades_joint</joint_name>
        <sub_topic>servo_2</sub_topic>
      </plugin>
      <plugin name='gz::sim::systems::JointController' filename='gz-sim-joint-controller-system'>
        <joint_name>engine_visual_joint</joint_name>
        <sub_topic>servo_3</sub_topic>
        <p_gain>10.0</p_gain>
      </plugin>
      <plugin name='gz::sim::systems::JointController' filename='gz-sim-joint-controller-system'>
        <joint_name>alarm_visual_joint</joint_name>
        <sub_topic>servo_4</sub_topic>
        <p_gain>1.0</p_gain>
        <cmd_max>2000.0</cmd_max>
        <cmd_min>1000.0</cmd_min>
        <cmd_offset>0.0</cmd_offset>
      </plugin>
      <plugin name='gz::sim::systems::JointStatePublisher' filename='gz-sim-joint-state-publisher-system'>
        <joint_name>left_wheel_joint</joint_name>
        <joint_name>right_wheel_joint</joint_name>
      </plugin>
      <static>0</static>
    </model>
    <model name='pallet1'>
      <pose>1.97116 -1.57042 0.07 0 -0 0</pose>
      <self_collide>0</self_collide>
      <link name='pallet_base'>
        <pose>0 0 0 0 -0 0</pose>
        <collision name='pallet_top_collision'>
          <pose>0 0 0.125 0 -0 0</pose>
          <geometry>
            <box>
              <size>1.22 0.8 0.04</size>
            </box>
          </geometry>
          <max_contacts>10</max_contacts>
          <surface>
            <contact>
              <ode/>
            </contact>
            <bounce/>
            <friction>
              <torsional>
                <ode/>
              </torsional>
              <ode/>
            </friction>
          </surface>
        </collision>
        <collision name='pallet_center_collision'>
          <pose>0 0 0.055 0 -0 0</pose>
          <geometry>
            <box>
              <size>1.22 0.1 0.1</size>
            </box>
          </geometry>
          <max_contacts>10</max_contacts>
          <surface>
            <contact>
              <ode/>
            </contact>
            <bounce/>
            <friction>
              <torsional>
                <ode/>
              </torsional>
              <ode/>
            </friction>
          </surface>
        </collision>
        <collision name='pallet_left_collision'>
          <pose>0 -0.35 0.055 0 -0 0</pose>
          <geometry>
            <box>
              <size>1.22 0.1 0.1</size>
            </box>
          </geometry>
          <max_contacts>10</max_contacts>
          <surface>
            <contact>
              <ode/>
            </contact>
            <bounce/>
            <friction>
              <torsional>
                <ode/>
              </torsional>
              <ode/>
            </friction>
          </surface>
        </collision>
        <collision name='pallet_right_collision'>
          <pose>0 0.35 0.055 0 -0 0</pose>
          <geometry>
            <box>
              <size>1.22 0.1 0.1</size>
            </box>
          </geometry>
          <max_contacts>10</max_contacts>
          <surface>
            <contact>
              <ode/>
            </contact>
            <bounce/>
            <friction>
              <torsional>
                <ode/>
              </torsional>
              <ode/>
            </friction>
          </surface>
        </collision>
        <visual name='pallet_visual'>
          <pose>0 0 0 0 -0 0</pose>
          <geometry>
            <mesh>
              <scale>1 1 1</scale>
              <uri>https://fuel.ignitionrobotics.org/1.0/mark/models/pallet/1/files/meshes/pallet.dae</uri>
            </mesh>
          </geometry>
        </visual>
        <self_collide>0</self_collide>
        <inertial>
          <pose>0 0 0 0 -0 0</pose>
          <inertia>
            <ixx>1</ixx>
            <ixy>0</ixy>
            <ixz>0</ixz>
            <iyy>1</iyy>
            <iyz>0</iyz>
            <izz>1</izz>
          </inertia>
          <mass>1</mass>
        </inertial>
        <enable_wind>0</enable_wind>
        <kinematic>0</kinematic>
      </link>
      <static>0</static>
    </model>
    <model name='Construction Cone'>
      <link name='link'>
        <collision name='collision'>
          <geometry>
            <mesh>
              <scale>10 10 10</scale>
              <uri>model://construction_cone/meshes/construction_cone.dae</uri>
            </mesh>
          </geometry>
          <max_contacts>10</max_contacts>
          <surface>
            <contact>
              <ode/>
            </contact>
            <bounce/>
            <friction>
              <torsional>
                <ode/>
              </torsional>
              <ode/>
            </friction>
          </surface>
        </collision>
        <visual name='visual'>
          <geometry>
            <mesh>
              <scale>10 10 10</scale>
              <uri>model://construction_cone/meshes/construction_cone.dae</uri>
            </mesh>
          </geometry>
        </visual>
        <self_collide>0</self_collide>
        <inertial>
          <pose>0 0 0 0 -0 0</pose>
          <inertia>
            <ixx>1</ixx>
            <ixy>0</ixy>
            <ixz>0</ixz>
            <iyy>1</iyy>
            <iyz>0</iyz>
            <izz>1</izz>
          </inertia>
          <mass>1</mass>
        </inertial>
        <enable_wind>0</enable_wind>
        <kinematic>0</kinematic>
      </link>
      <pose>0.607896 3.89236 0 0 -0 0</pose>
    </model>
    <state world_name='default'>
      <sim_time>1868 226000000</sim_time>
      <real_time>2185 469751558</real_time>
      <wall_time>1709687733 893300721</wall_time>
      <iterations>1868226</iterations>
      <model name='Construction Cone'>
        <pose>0.607896 3.89236 -0 0 -1e-06 0</pose>
        <scale>1 1 1</scale>
        <link name='link'>
          <pose>0.607896 3.89236 -0 0 -1e-06 0</pose>
          <velocity>0 0 0 0 -0 0</velocity>
          <acceleration>-0 0 0.008512 2.58585 -1.13682 -3.14159</acceleration>
          <wrench>-0 0 0.008512 0 -0 0</wrench>
        </link>
      </model>
      <model name='Electrical_Array_8'>
        <pose>2.95506 1.35848 0 0 -0 0</pose>
        <scale>1 1 1</scale>
        <link name='link'>
          <pose>2.95506 1.35848 0 0 -0 0</pose>
          <velocity>0 0 0 0 -0 0</velocity>
          <acceleration>0 0 0 0 -0 0</acceleration>
          <wrench>0 0 0 0 -0 0</wrench>
        </link>
      </model>
      <model name='Sofa'>
        <pose>4.85009 3.88316 0.000125 1e-06 1.3e-05 -2.02329</pose>
        <scale>1 1 1</scale>
        <link name='link'>
          <pose>4.85009 3.88316 0.000125 1.3e-05 -1e-06 -0.452491</pose>
          <velocity>0 0 0 0 -0 0</velocity>
          <acceleration>-0.000753 0.001065 1.50894 -2.12558 0.303105 3e-06</acceleration>
          <wrench>-0.000753 0.001065 1.50894 0 -0 0</wrench>
        </link>
      </model>
      <model name='ground_plane'>
        <pose>0 0 0 0 -0 0</pose>
        <scale>1 1 1</scale>
        <link name='link'>
          <pose>0 0 0 0 -0 0</pose>
          <velocity>0 0 0 0 -0 0</velocity>
          <acceleration>0 0 0 0 -0 0</acceleration>
          <wrench>0 0 0 0 -0 0</wrench>
        </link>
      </model>
      <model name='pallet1'>
        <pose>1.97116 -1.57042 -0.005 -0 -0 -0</pose>
        <scale>1 1 1</scale>
        <link name='pallet_base'>
          <pose>1.97116 -1.57042 -0.005 -0 -0 -0</pose>
          <velocity>0 0 0 0 -0 0</velocity>
          <acceleration>0 0 -9.8 0 -0 0</acceleration>
          <wrench>0 0 -9.8 0 -0 0</wrench>
        </link>
      </model>
      <model name='robot'>
        <pose>2.8197 0.000798 0.033743 1e-06 2.6e-05 0.000217</pose>
        <scale>1 1 1</scale>
        <link name='base_link'>
          <pose>2.8197 0.000798 0.033743 1e-06 2.6e-05 0.000217</pose>
          <velocity>0.000857 -2.4e-05 -0.006745 0.000777 0.025113 -4.3e-05</velocity>
          <acceleration>6.9e-05 0.002713 -9.8065 -0.074939 -0.120922 -0.070415</acceleration>
          <wrench>6.2e-05 0.002441 -8.82585 0 -0 0</wrench>
        </link>
        <link name='left_wheel_link'>
          <pose>2.81967 0.113298 0.033743 -1.5708 0.936194 0.000216</pose>
          <velocity>0.000854 -1.4e-05 -0.006639 0.000346 0.025113 -3.6e-05</velocity>
          <acceleration>0.000648 0.028754 -9.79203 -0.925852 -0.094033 -0.106949</acceleration>
          <wrench>0.000324 0.014377 -4.89601 0 -0 0</wrench>
        </link>
        <link name='right_wheel_link'>
          <pose>2.81972 -0.111702 0.033743 1.5708 0.903011 0.00022</pose>
          <velocity>0.000851 -4.5e-05 -0.006824 0.001276 0.025113 1.7e-05</velocity>
          <acceleration>-0.000772 -0.033637 -9.79628 0.939493 -0.070098 0.111697</acceleration>
          <wrench>-0.000386 -0.016818 -4.89814 0 -0 0</wrench>
        </link>
      </model>
      <model name='zero_turn_mower'>
        <pose>5.11378 -1.31843 0.195745 0 -0.005005 -0.004467</pose>
        <scale>1 1 1</scale>
        <link name='alarm_visual_link'>
          <pose>4.66054 -1.31641 0.843484 -2.3e-05 -0.005005 0.000202</pose>
          <velocity>2.5e-05 -9.1e-05 6.2e-05 3e-06 4.7e-05 4e-06</velocity>
          <acceleration>-0.041805 -0.428707 -0.071889 0.003599 -0.056381 1.9e-05</acceleration>
          <wrench>-0.041805 -0.428707 -0.071889 0 -0 0</wrench>
        </link>
        <link name='base_link'>
          <pose>5.11378 -1.31843 0.195745 0 -0.005005 -0.004467</pose>
          <velocity>-5e-06 -8.9e-05 4.1e-05 2e-06 4.7e-05 -2e-06</velocity>
          <acceleration>-0.004828 -0.331454 -0.046304 0.006011 -0.056377 0.198906</acceleration>
          <wrench>-1.06217 -72.9199 -10.187 0 -0 0</wrench>
        </link>
        <link name='cutter_blades_link'>
          <pose>5.31428 -1.31933 0.096747 -2.3e-05 -0.005005 0.000202</pose>
          <velocity>-1e-05 -9e-05 3.2e-05 3e-06 4.7e-05 4e-06</velocity>
          <acceleration>0.000881 -0.295105 -0.035042 0.003584 -0.056381 1.9e-05</acceleration>
          <wrench>0.000881 -0.295105 -0.035042 0 -0 0</wrench>
        </link>
        <link name='engine_visual_link'>
          <pose>4.2113 -1.3144 0.691234 1e-05 -0.005005 -0.004467</pose>
          <velocity>1.8e-05 -8.9e-05 8.4e-05 -0 4.7e-05 -2e-06</velocity>
          <acceleration>-0.033627 -0.518963 -0.097212 -0.00126 -0.05636 0.201517</acceleration>
          <wrench>-0.033627 -0.518963 -0.097212 0 -0 0</wrench>
        </link>
        <link name='left_wheel_link'>
          <pose>4.6657 -0.866425 0.214992 1.57096 1.56965 3.13729</pose>
          <velocity>-5e-06 -3.9e-05 6.8e-05 0.000175 -2.3e-05 1e-06</velocity>
          <acceleration>-0.1034 -0.187096 -0.067338 0.828686 -0.191295 0.372291</acceleration>
          <wrench>-0.827198 -1.49676 -0.538706 0 -0 0</wrench>
        </link>
        <link name='right_wheel_link'>
          <pose>4.66168 -1.76642 0.214992 -1.57081 1.55393 -0.004476</pose>
          <velocity>-4e-06 -3.9e-05 5.7e-05 0.000176 -1.9e-05 -3e-06</velocity>
          <acceleration>0.097189 -0.188579 -0.073398 0.833169 0.276497 0.445065</acceleration>
          <wrench>0.777515 -1.50863 -0.587181 0 -0 0</wrench>
        </link>
      </model>
      <light name='sun'>
        <pose>0 0 10 0 -0 0</pose>
      </light>
    </state>
    <gui fullscreen='0'>
      <camera name='user_camera'>
        <pose>6.53492 -5.06405 3.43522 0 0.48858 2.00932</pose>
        <view_controller>orbit</view_controller>
        <projection_type>perspective</projection_type>
      </camera>
    </gui>
  </world>
</sdf>
